Workbook

Sheet 中国_中债国债到期收益率_1年
A1: 日期 | B1: 中债国债到期收益率:1年 | C1: 中债国债到期收益率:5年 | D1: 中国:中债国债到期收益率:10年 | E1: 中债国债到期收益率:30年 | F1: 利率互换:FR007:1年 | G1: 利率互换:FR007:5年 | H1: FR007
A2: 44713 | B2: =[1]!WSD("S0059744,S0059747,S0059749,S0059752,M0048486,M0048490,M0017153","EDBclose","2022-06-01","","TradingCalendar=SSE","PriceAdj=F","rptType=1","ShowCodes=N","ShowParams=Y","cols=7;rows=622") -> #NAME? | C2: 2.5594 | D2: 2.7551 | E2: 3.2643 | F2: 2.0815 | G2: 2.5254 | H2: 1.64
A3: 44714 | B3: 1.9564 | C3: 2.563 | D3: 2.7601 | E3: 3.2669 | F3: 2.0917 | G3: 2.5397 | H3: 1.65
A4: 44718 | B4: 2.0199 | C4: 2.5994 | D4: 2.7776 | E4: 3.2745 | F4: 2.1125 | G4: 2.5583 | H4: 1.68
A5: 44719 | B5: 2.018 | C5: 2.5842 | D5: 2.7576 | E5: 3.2671 | F5: 2.12 | G5: 2.5627 | H5: 1.65
A6: 44720 | B6: 2.0282 | C6: 2.585 | D6: 2.7661 | E6: 3.2746 | F6: 2.1052 | G6: 2.55 | H6: 1.65
A7: 44721 | B7: 2.0151 | C7: 2.5726 | D7: 2.7576 | E7: 3.2646 | F7: 2.0984 | G7: 2.5421 | H7: 1.65
A8: 44722 | B8: 2.0051 | C8: 2.568 | D8: 2.7526 | E8: 3.2622 | F8: 2.0934 | G8: 2.5368 | H8: 1.62
A9: 44725 | B9: 2.0026 | C9: 2.5899 | D9: 2.7652 | E9: 3.2698 | F9: 2.1035 | G9: 2.5507 | H9: 1.65
A10: 44726 | B10: 2.0176 | C10: 2.5952 | D10: 2.7702 | E10: 3.2698 | F10: 2.1193 | G10: 2.5675 | H10: 1.63
A11: 44727 | B11: 2.036 | C11: 2.6112 | D11: 2.7827 | E11: 3.2722 | F11: 2.127 | G11: 2.5755 | H11: 1.63
A12: 44728 | B12: 2.0352 | C12: 2.5936 | D12: 2.7728 | E12: 3.2623 | F12: 2.1182 | G12: 2.5698 | H12: 1.65
A13: 44729 | B13: 2.0102 | C13: 2.5944 | D13: 2.7752 | E13: 3.2598 | F13: 2.1058 | G13: 2.5594 | H13: 1.7
A14: 44732 | B14: 2.0056 | C14: 2.6163 | D14: 2.7853 | E14: 3.2674 | F14: 2.1311 | G14: 2.5829 | H14: 1.7
... A144: 44918 | B144: 2.2269 | C144: 2.6062 | D144: 2.8251 | E144: 3.2152 | F144: 2.1688 | G144: 2.7376 | H144: 1.8
A145: 44921 | B145: 2.2469 | C145: 2.6276 | D145: 2.8378 | E145: 3.2202 | H145: 2.0558
A146: 44922 | B146: 2.2469 | C146: 2.6703 | D146: 2.8657 | E146: 3.2175 | F146: 2.2315 | G146: 2.7833 | H146: 5
A147: 44923 | B147: 2.2369 | C147: 2.6704 | D147: 2.8503 | E147: 3.2127 | F147: 2.2309 | G147: 2.7813 | H147: 4.8
A148: 44924 | B148: 2.1669 | C148: 2.6382 | D148: 2.8376 | E148: 3.1926 | F148: 2.2007 | G148: 2.7574 | H148: 3.5
A149: 44925 | B149: 2.0969 | C149: 2.6446 | D149: 2.8353 | E149: 3.1952 | F149: 2.1801 | G149: 2.759 | H149: 3
A150: 44926 | B150: 2.0969 | C150: 2.6446 | D150: 2.8353 | E150: 3.1952
A151: 44929 | B151: 2.112 | C151: 2.6298 | D151: 2.8228 | E151: 3.193 | F151: 2.1752 | G151: 2.7651 | H151: 1.9243
A152: 44930 | B152: 2.067 | C152: 2.6071 | D152: 2.8103 | E152: 3.1931 | F152: 2.1469 | G152: 2.7342 | H152: 1.7
A153: 44931 | B153: 2.082 | C153: 2.625 | D153: 2.8304 | E153: 3.2056 | F153: 2.144 | G153: 2.7366 | H153: 1.7
A154: 44932 | B154: 2.097 | C154: 2.6495 | D154: 2.8328 | E154: 3.2106 | F154: 2.1611 | G154: 2.7604 | H154: 1.75
A155: 44935 | B155: 2.0996 | C155: 2.6649 | D155: 2.8428 | E155: 3.2156 | F155: 2.1796 | G155: 2.7701 | H155: 1.85
A156: 44936 | B156: 2.122 | C156: 2.7104 | D156: 2.8602 | E156: 3.2331 | F156: 2.2331 | G156: 2.8136 | H156: 1.98
A157: 44937 | B157: 2.127 | C157: 2.6989 | D157: 2.8603 | E157: 3.2331 | F157: 2.2547 | G157: 2.8284 | H157: 2.3
A158: 44938 | B158: 2.097 | C158: 2.6974 | D158: 2.8778 | E158: 3.2378 | F158: 2.2357 | G158: 2.8169 | H158: 2.2
A159: 44939 | B159: 2.097 | C159: 2.7096 | D159: 2.901 | E159: 3.2476 | F159: 2.2449 | G159: 2.8414 | H159: 1.95
A160: 44942 | B160: 2.127 | C160: 2.7571 | D160: 2.9167 | E160: 3.2677 | F160: 2.2877 | G160: 2.8972 | H160: 2.15
A161: 44943 | B161: 2.127 | C161: 2.7346 | D161: 2.9017 | E161: 3.2531 | F161: 2.297 | G161: 2.8954 | H161: 2.6
A162: 44944 | B162: 2.1615 | C162: 2.7257 | D162: 2.9222 | E162: 3.2754 | F162: 2.2933 | G162: 2.8874 | H162: 2.6
... A164: 44946 | B164: 2.1648 | C164: 2.7288 | D164: 2.9331 | E164: 3.2779 | F164: 2.2937 | G164: 2.9066 | H164: 2
A165: 44954 | B165: 2.1496 | C165: 2.7283 | D165: 2.9341 | E165: 3.283 | G165: 2.9434 | H165: 1.95
A166: 44955 | B166: 2.1519 | C166: 2.7225 | D166: 2.9219 | E166: 3.2805 | H166: 1.854
A167: 44956 | B167: 2.176 | C167: 2.7238 | D167: 2.9133 | E167: 3.2782 | F167: 2.3007 | G167: 2.9292 | H167: 2.14
A168: 44957 | B168: 2.1535 | C168: 2.7039 | D168: 2.8977 | E168: 3.2793 | F168: 2.2868 | G168: 2.9067 | H168: 2.2
A169: 44958 | B169: 2.1631 | C169: 2.7091 | D169: 2.9101 | E169: 3.2889 | F169: 2.2814 | G169: 2.9032 | H169: 2.05
A170: 44959 | B170: 2.1507 | C170: 2.6945 | D170: 2.897 | E170: 3.2853 | F170: 2.266 | G170: 2.8845 | H170: 2.05
...

Sheet Return
A1: 日期
A2: 44713
A3: 44714
A4: 44718 | B4: =-中国_中债国债到期收益率_1年!B3+中国_中债国债到期收益率_1年!B2 -> #NAME? | C4: =-中国_中债国债到期收益率_1年!C3+中国_中债国债到期收益率_1年!C2 -> -0.0036 | D4: =-中国_中债国债到期收益率_1年!D3+中国_中债国债到期收益率_1年!D2 -> -0.005 | E4: =-中国_中债国债到期收益率_1年!E3+中国_中债国债到期收益率_1年!E2 -> -0.0026 | F4: =-中国_中债国债到期收益率_1年!F3+中国_中债国债到期收益率_1年!F2 -> -0.0102 | G4: =-中国_中债国债到期收益率_1年!G3+中国_中债国债到期收益率_1年!G2 -> -0.0143
A5: 44719 | B5: =-中国_中债国债到期收益率_1年!B4+中国_中债国债到期收益率_1年!B3 -> -0.0635 | C5: =-中国_中债国债到期收益率_1年!C4+中国_中债国债到期收益率_1年!C3 -> -0.0364 | D5: =-中国_中债国债到期收益率_1年!D4+中国_中债国债到期收益率_1年!D3 -> -0.0175 | E5: =-中国_中债国债到期收益率_1年!E4+中国_中债国债到期收益率_1年!E3 -> -0.0076 | F5: =-中国_中债国债到期收益率_1年!F4+中国_中债国债到期收益率_1年!F3 -> -0.0208 | G5: =-中国_中债国债到期收益率_1年!G4+中国_中债国债到期收益率_1年!G3 -> -0.0186
A6: 44720 | B6: =-中国_中债国债到期收益率_1年!B5+中国_中债国债到期收益率_1年!B4 -> 0.0019 | C6: =-中国_中债国债到期收益率_1年!C5+中国_中债国债到期收益率_1年!C4 -> 0.0152 | D6: =-中国_中债国债到期收益率_1年!D5+中国_中债国债到期收益率_1年!D4 -> 0.02 | E6: =-中国_中债国债到期收益率_1年!E5+中国_中债国债到期收益率_1年!E4 -> 0.0074 | F6: =-中国_中债国债到期收益率_1年!F5+中国_中债国债到期收益率_1年!F4 -> -0.0075 | G6: =-中国_中债国债到期收益率_1年!G5+中国_中债国债到期收益率_1年!G4 -> -0.0044
A7: 44721 | B7: =-中国_中债国债到期收益率_1年!B6+中国_中债国债到期收益率_1年!B5 -> -0.0102 | C7: =-中国_中债国债到期收益率_1年!C6+中国_中债国债到期收益率_1年!C5 -> -0.0008 | D7: =-中国_中债国债到期收益率_1年!D6+中国_中债国债到期收益率_1年!D5 -> -0.0085 | E7: =-中国_中债国债到期收益率_1年!E6+中国_中债国债到期收益率_1年!E5 -> -0.0075 | F7: =-中国_中债国债到期收益率_1年!F6+中国_中债国债到期收益率_1年!F5 -> 0.0148 | G7: =-中国_中债国债到期收益率_1年!G6+中国_中债国债到期收益率_1年!G5 -> 0.0127
A8: 44722 | B8: =-中国_中债国债到期收益率_1年!B7+中国_中债国债到期收益率_1年!B6 -> 0.0131 | C8: =-中国_中债国债到期收益率_1年!C7+中国_中债国债到期收益率_1年!C6 -> 0.0124 | D8: =-中国_中债国债到期收益率_1年!D7+中国_中债国债到期收益率_1年!D6 -> 0.0085 | E8: =-中国_中债国债到期收益率_1年!E7+中国_中债国债到期收益率_1年!E6 -> 0.01 | F8: =-中国_中债国债到期收益率_1年!F7+中国_中债国债到期收益率_1年!F6 -> 0.0068 | G8: =-中国_中债国债到期收益率_1年!G7+中国_中债国债到期收益率_1年!G6 -> 0.0079
A9: 44725 | B9: =-中国_中债国债到期收益率_1年!B8+中国_中债国债到期收益率_1年!B7 -> 0.01 | C9: =-中国_中债国债到期收益率_1年!C8+中国_中债国债到期收益率_1年!C7 -> 0.0046 | D9: =-中国_中债国债到期收益率_1年!D8+中国_中债国债到期收益率_1年!D7 -> 0.005 | E9: =-中国_中债国债到期收益率_1年!E8+中国_中债国债到期收益率_1年!E7 -> 0.0024 | F9: =-中国_中债国债到期收益率_1年!F8+中国_中债国债到期收益率_1年!F7 -> 0.005 | G9: =-中国_中债国债到期收益率_1年!G8+中国_中债国债到期收益率_1年!G7 -> 0.0053
A10: 44726 | B10: =-中国_中债国债到期收益率_1年!B9+中国_中债国债到期收益率_1年!B8 -> 0.0025 | C10: =-中国_中债国债到期收益率_1年!C9+中国_中债国债到期收益率_1年!C8 -> -0.0219 | D10: =-中国_中债国债到期收益率_1年!D9+中国_中债国债到期收益率_1年!D8 -> -0.0126 | E10: =-中国_中债国债到期收益率_1年!E9+中国_中债国债到期收益率_1年!E8 -> -0.0076 | F10: =-中国_中债国债到期收益率_1年!F9+中国_中债国债到期收益率_1年!F8 -> -0.0101 | G10: =-中国_中债国债到期收益率_1年!G9+中国_中债国债到期收益率_1年!G8 -> -0.0139
A11: 44727 | B11: =-中国_中债国债到期收益率_1年!B10+中国_中债国债到期收益率_1年!B9 -> -0.015 | C11: =-中国_中债国债到期收益率_1年!C10+中国_中债国债到期收益率_1年!C9 -> -0.0053 | D11: =-中国_中债国债到期收益率_1年!D10+中国_中债国债到期收益率_1年!D9 -> -0.005 | E11: =-中国_中债国债到期收益率_1年!E10+中国_中债国债到期收益率_1年!E9 -> 0 | F11: =-中国_中债国债到期收益率_1年!F10+中国_中债国债到期收益率_1年!F9 -> -0.0158 | G11: =-中国_中债国债到期收益率_1年!G10+中国_中债国债到期收益率_1年!G9 -> -0.0168
A12: 44728 | B12: =-中国_中债国债到期收益率_1年!B11+中国_中债国债到期收益率_1年!B10 -> -0.0184 | C12: =-中国_中债国债到期收益率_1年!C11+中国_中债国债到期收益率_1年!C10 -> -0.016 | D12: =-中国_中债国债到期收益率_1年!D11+中国_中债国债到期收益率_1年!D10 -> -0.0125 | E12: =-中国_中债国债到期收益率_1年!E11+中国_中债国债到期收益率_1年!E10 -> -0.0024 | F12: =-中国_中债国债到期收益率_1年!F11+中国_中债国债到期收益率_1年!F10 -> -0.0077 | G12: =-中国_中债国债到期收益率_1年!G11+中国_中债国债到期收益率_1年!G10 -> -0.008
A13: 44729 | B13: =-中国_中债国债到期收益率_1年!B12+中国_中债国债到期收益率_1年!B11 -> 0.0008 | C13: =-中国_中债国债到期收益率_1年!C12+中国_中债国债到期收益率_1年!C11 -> 0.0176 | D13: =-中国_中债国债到期收益率_1年!D12+中国_中债国债到期收益率_1年!D11 -> 0.0099 | E13: =-中国_中债国债到期收益率_1年!E12+中国_中债国债到期收益率_1年!E11 -> 0.0099 | F13: =-中国_中债国债到期收益率_1年!F12+中国_中债国债到期收益率_1年!F11 -> 0.0088 | G13: =-中国_中债国债到期收益率_1年!G12+中国_中债国债到期收益率_1年!G11 -> 0.0057
A14: 44732 | B14: =-中国_中债国债到期收益率_1年!B13+中国_中债国债到期收益率_1年!B12 -> 0.025 | C14: =-中国_中债国债到期收益率_1年!C13+中国_中债国债到期收益率_1年!C12 -> -0.0008 | D14: =-中国_中债国债到期收益率_1年!D13+中国_中债国债到期收益率_1年!D12 -> -0.0024 | E14: =-中国_中债国债到期收益率_1年!E13+中国_中债国债到期收益率_1年!E12 -> 0.0025 | F14: =-中国_中债国债到期收益率_1年!F13+中国_中债国债到期收益率_1年!F12 -> 0.0124 | G14: =-中国_中债国债到期收益率_1年!G13+中国_中债国债到期收益率_1年!G12 -> 0.0104
A15: 44733 | B15: =-中国_中债国债到期收益率_1年!B14+中国_中债国债到期收益率_1年!B13 -> 0.0046 | C15: =-中国_中债国债到期收益率_1年!C14+中国_中债国债到期收益率_1年!C13 -> -0.0219 | D15: =-中国_中债国债到期收益率_1年!D14+中国_中债国债到期收益率_1年!D13 -> -0.0101 | E15: =-中国_中债国债到期收益率_1年!E14+中国_中债国债到期收益率_1年!E13 -> -0.0076 | F15: =-中国_中债国债到期收益率_1年!F14+中国_中债国债到期收益率_1年!F13 -> -0.0253 | G15: =-中国_中债国债到期收益率_1年!G14+中国_中债国债到期收益率_1年!G13 -> -0.0235
... A622: 45616 | B622: =-中国_中债国债到期收益率_1年!B621+中国_中债国债到期收益率_1年!B620 -> 0.0124 | C622: =-中国_中债国债到期收益率_1年!C621+中国_中债国债到期收益率_1年!C620 -> 0.0118 | D622: =-中国_中债国债到期收益率_1年!D621+中国_中债国债到期收益率_1年!D620 -> 0.017 | E622: =-中国_中债国债到期收益率_1年!E621+中国_中债国债到期收益率_1年!E620 -> 0.0315 | F622: =-中国_中债国债到期收益率_1年!F621+中国_中债国债到期收益率_1年!F620 -> 0.0035 | G622: =-中国_中债国债到期收益率_1年!G621+中国_中债国债到期收益率_1年!G620 -> 0.0037

Sheet PnL
A1: 日期 | B1: Bond1Y | C1: Bond5Y | D1: Bond10Y | E1: Bond30Y | F1: Sum | G1: Bond1Y | H1: Bond5Y | I1: Bond10Y | J1: Bond30Y | K1: Sum | L1: DVBond1Y | M1: Bond5Y | N1: Bond10Y | O1: Bond30Y | P1: Sum | Q1: Capcumsum | R1: CarryBond1Y | S1: Bond5Y | T1: Bond10Y | U1: Bond30Y | V1: Sum | W1: Carrycumsum | X1: Cost | Y1: CostCum | Z1: IRS1Y | AA1: IRS5Y | AB1: IRS1YPnL | AC1: IRS5YPnL | AD1: cumsum | AE1: total | AF1: NetValue | AG1: daliyRet | AH1: MDD | AI1: 500000
A2: 44713 | B2: 20 | C2: 10 | D2: 30 | F2: =SUM(B2:E2) -> 60 | G2: =B2 -> 20 | H2: =5*C2 -> 50 | I2: =9*D2 -> 270 | J2: =16*E2 -> 0 | K2: =SUM(G2:J2) -> 340
A3: 44714 | B3: 20 | C3: 10 | D3: 30 | F3: =SUM(B3:E3) -> 60 | G3: =B3 -> 20 | H3: =5*C3 -> 50 | I3: =9*D3 -> 270 | J3: =16*E3 -> 0 | K3: =SUM(G3:J3) -> 340 | L3: =G3*Return!B3*100 -> 0 | M3: =H3*Return!C3*100 -> 0 | N3: =I3*Return!D3*100 -> 0 | O3: =J3*Return!E3*100 -> 0 | P3: =SUM(L3:O3) -> 0 | Q3: =SUM($P$3:P3) -> 0 | R3: =B3*中国_中债国债到期收益率_1年!B2/365*100 -> #NAME? | S3: =C3*中国_中债国债到期收益率_1年!C2/365*100 -> 7.0120548 | T3: =D3*中国_中债国债到期收益率_1年!D2/365*100 -> 22.644658 | U3: =E3*中国_中债国债到期收益率_1年!E2/365*100 -> 0 | V3: =SUM(R3:U3) -> #NAME? | W3: =SUM($V$3:V3) -> #NAME? | X3: =MAX(F3-50,0)*中国_中债国债到期收益率_1年!H3*100/365 -> 4.5205479 | Y3: =SUM($X$3:X3) -> 4.5205479 | AB3: =Z3*Return!F3*100 -> 0 | AD3: =SUM($AB$3:AB3)+SUM($AC$3:AC3) -> 0 | AE3: =Q3+W3+AD3-Y3 -> #NAME? | AF3: =AE3/$AI$1+1 -> #NAME?
A4: 44718 | B4: 20 | C4: 10 | D4: 30 | F4: =SUM(B4:E4) -> 60 | G4: =B4 -> 20 | H4: =5*C4 -> 50 | I4: =9*D4 -> 270 | J4: =16*E4 -> 0 | K4: =SUM(G4:J4) -> 340 | L4: =G4*Return!B4*100 -> #NAME? | M4: =H4*Return!C4*100 -> -18 | N4: =I4*Return!D4*100 -> -135 | O4: =J4*Return!E4*100 -> 0 | P4: =SUM(L4:O4) -> #NAME? | Q4: =SUM($P$3:P4) -> #NAME? | R4: =B4*中国_中债国债到期收益率_1年!B3/365*100 -> 10.72 | S4: =C4*中国_中债国债到期收益率_1年!C3/365*100 -> 7.0219178 | T4: =D4*中国_中债国债到期收益率_1年!D3/365*100 -> 22.685753 | U4: =E4*中国_中债国债到期收益率_1年!E3/365*100 -> 0 | V4: =SUM(R4:U4) -> 40.427671 | W4: =SUM($V$3:V4) -> #NAME? | X4: =MAX(F4-50,0)*中国_中债国债到期收益率_1年!H4*100/365 -> 4.6027397 | Y4: =SUM($X$3:X4) -> 9.1232877 | AB4: =Z4*Return!F4*100 -> 0 | AD4: =SUM($AB$3:AB4)+SUM($AC$3:AC4) -> 0 | AE4: =Q4+W4+AD4-Y4 -> #NAME? | AF4: =AE4/$AI$1+1 -> #NAME? | AG4: =(AF4/AF3-1)-中国_中债国债到期收益率_1年!H4%/252 -> #NAME? | AH4: =MIN((AF4-MAX($AF$3:AF4))/MAX($AF$3:AF4),0) -> #NAME?
A5: 44719 | B5: 20 | C5: 10 | D5: 30 | F5: =SUM(B5:E5) -> 60 | G5: =B5 -> 20 | H5: =5*C5 -> 50 | I5: =9*D5 -> 270 | J5: =16*E5 -> 0 | K5: =SUM(G5:J5) -> 340 | L5: =G5*Return!B5*100 -> -127 | M5: =H5*Return!C5*100 -> -182 | N5: =I5*Return!D5*100 -> -472.5 | O5: =J5*Return!E5*100 -> 0 | P5: =SUM(L5:O5) -> -781.5 | Q5: =SUM($P$3:P5) -> #NAME? | R5: =B5*中国_中债国债到期收益率_1年!B4/365*100 -> 11.067945 | S5: =C5*中国_中债国债到期收益率_1年!C4/365*100 -> 7.1216438 | T5: =D5*中国_中债国债到期收益率_1年!D4/365*100 -> 22.829589 | U5: =E5*中国_中债国债到期收益率_1年!E4/365*100 -> 0 | V5: =SUM(R5:U5) -> 41.019178 | W5: =SUM($V$3:V5) -> #NAME? | X5: =MAX(F5-50,0)*中国_中债国债到期收益率_1年!H5*100/365 -> 4.5205479 | Y5: =SUM($X$3:X5) -> 13.643836 | AB5: =Z5*Return!F5*100 -> 0 | AD5: =SUM($AB$3:AB5)+SUM($AC$3:AC5) -> 0 | AE5: =Q5+W5+AD5-Y5 -> #NAME? | AF5: =AE5/$AI$1+1 -> #NAME? | AG5: =(AF5/AF4-1)-中国_中债国债到期收益率_1年!H5%/252 -> #NAME? | AH5: =MIN((AF5-MAX($AF$3:AF5))/MAX($AF$3:AF5),0) -> #NAME?
A6: 44720 | B6: 20 | C6: 10 | D6: 30 | F6: =SUM(B6:E6) -> 60 | G6: =B6 -> 20 | H6: =5*C6 -> 50 | I6: =9*D6 -> 270 | J6: =16*E6 -> 0 | K6: =SUM(G6:J6) -> 340 | L6: =G6*Return!B6*100 -> 3.8 | M6: =H6*Return!C6*100 -> 76 | N6: =I6*Return!D6*100 -> 540 | O6: =J6*Return!E6*100 -> 0 | P6: =SUM(L6:O6) -> 619.8 | Q6: =SUM($P$3:P6) -> #NAME? | R6: =B6*中国_中债国债到期收益率_1年!B5/365*100 -> 11.057534 | S6: =C6*中国_中债国债到期收益率_1年!C5/365*100 -> 7.08 | T6: =D6*中国_中债国债到期收益率_1年!D5/365*100 -> 22.665205 | U6: =E6*中国_中债国债到期收益率_1年!E5/365*100 -> 0 | V6: =SUM(R6:U6) -> 40.80274 | W6: =SUM($V$3:V6) -> #NAME? | X6: =MAX(F6-50,0)*中国_中债国债到期收益率_1年!H6*100/365 -> 4.5205479 | Y6: =SUM($X$3:X6) -> 18.164384 | AB6: =Z6*Return!F6*100 -> 0 | AD6: =SUM($AB$3:AB6)+SUM($AC$3:AC6) -> 0 | AE6: =Q6+W6+AD6-Y6 -> #NAME? | AF6: =AE6/$AI$1+1 -> #NAME? | AG6: =(AF6/AF5-1)-中国_中债国债到期收益率_1年!H6%/252 -> #NAME? | AH6: =MIN((AF6-MAX($AF$3:AF6))/MAX($AF$3:AF6),0) -> #NAME?
A7: 44721 | B7: 20 | C7: 10 | D7: 30 | F7: =SUM(B7:E7) -> 60 | G7: =B7 -> 20 | H7: =5*C7 -> 50 | I7: =9*D7 -> 270 | J7: =16*E7 -> 0 | K7: =SUM(G7:J7) -> 340 | L7: =G7*Return!B7*100 -> -20.4 | M7: =H7*Return!C7*100 -> -4 | N7: =I7*Return!D7*100 -> -229.5 | O7: =J7*Return!E7*100 -> 0 | P7: =SUM(L7:O7) -> -253.9 | Q7: =SUM($P$3:P7) -> #NAME? | R7: =B7*中国_中债国债到期收益率_1年!B6/365*100 -> 11.113425 | S7: =C7*中国_中债国债到期收益率_1年!C6/365*100 -> 7.0821918 | T7: =D7*中国_中债国债到期收益率_1年!D6/365*100 -> 22.735068 | U7: =E7*中国_中债国债到期收益率_1年!E6/365*100 -> 0 | V7: =SUM(R7:U7) -> 40.930685 | W7: =SUM($V$3:V7) -> #NAME? | X7: =MAX(F7-50,0)*中国_中债国债到期收益率_1年!H7*100/365 -> 4.5205479 | Y7: =SUM($X$3:X7) -> 22.684932 | AB7: =Z7*Return!F7*100 -> 0 | AD7: =SUM($AB$3:AB7)+SUM($AC$3:AC7) -> 0 | AE7: =Q7+W7+AD7-Y7 -> #NAME? | AF7: =AE7/$AI$1+1 -> #NAME? | AG7: =(AF7/AF6-1)-中国_中债国债到期收益率_1年!H7%/252 -> #NAME? | AH7: =MIN((AF7-MAX($AF$3:AF7))/MAX($AF$3:AF7),0) -> #NAME?
A8: 44722 | B8: 20 | C8: 10 | D8: 30 | F8: =SUM(B8:E8) -> 60 | G8: =B8 -> 20 | H8: =5*C8 -> 50 | I8: =9*D8 -> 270 | J8: =16*E8 -> 0 | K8: =SUM(G8:J8) -> 340 | L8: =G8*Return!B8*100 -> 26.2 | M8: =H8*Return!C8*100 -> 62 | N8: =I8*Return!D8*100 -> 229.5 | O8: =J8*Return!E8*100 -> 0 | P8: =SUM(L8:O8) -> 317.7 | Q8: =SUM($P$3:P8) -> #NAME? | R8: =B8*中国_中债国债到期收益率_1年!B7/365*100 -> 11.041644 | S8: =C8*中国_中债国债到期收益率_1年!C7/365*100 -> 7.0482192 | T8: =D8*中国_中债国债到期收益率_1年!D7/365*100 -> 22.665205 | U8: =E8*中国_中债国债到期收益率_1年!E7/365*100 -> 0 | V8: =SUM(R8:U8) -> 40.755068 | W8: =SUM($V$3:V8) -> #NAME? | X8: =MAX(F8-50,0)*中国_中债国债到期收益率_1年!H8*100/365 -> 4.4383562 | Y8: =SUM($X$3:X8) -> 27.123288 | AB8: =Z8*Return!F8*100 -> 0 | AD8: =SUM($AB$3:AB8)+SUM($AC$3:AC8) -> 0 | AE8: =Q8+W8+AD8-Y8 -> #NAME? | AF8: =AE8/$AI$1+1 -> #NAME? | AG8: =(AF8/AF7-1)-中国_中债国债到期收益率_1年!H8%/252 -> #NAME? | AH8: =MIN((AF8-MAX($AF$3:AF8))/MAX($AF$3:AF8),0) -> #NAME?
A9: 44725 | B9: 20 | C9: 30 | D9: 30 | F9: =SUM(B9:E9) -> 80 | G9: =B9 -> 20 | H9: =5*C9 -> 150 | I9: =9*D9 -> 270 | J9: =16*E9 -> 0 | K9: =SUM(G9:J9) -> 440 | L9: =G9*Return!B9*100 -> 20 | M9: =H9*Return!C9*100 -> 69 | N9: =I9*Return!D9*100 -> 135 | O9: =J9*Return!E9*100 -> 0 | P9: =SUM(L9:O9) -> 224 | Q9: =SUM($P$3:P9) -> #NAME? | R9: =B9*中国_中债国债到期收益率_1年!B8/365*100 -> 10.986849 | S9: =C9*中国_中债国债到期收益率_1年!C8/365*100 -> 21.106849 | T9: =D9*中国_中债国债到期收益率_1年!D8/365*100 -> 22.62411 | U9: =E9*中国_中债国债到期收益率_1年!E8/365*100 -> 0 | V9: =SUM(R9:U9) -> 54.717808 | W9: =SUM($V$3:V9) -> #NAME? | X9: =MAX(F9-50,0)*中国_中债国债到期收益率_1年!H9*100/365 -> 13.561644 | Y9: =SUM($X$3:X9) -> 40.684932 | AB9: =Z9*Return!F9*100 -> 0 | AD9: =SUM($AB$3:AB9)+SUM($AC$3:AC9) -> 0 | AE9: =Q9+W9+AD9-Y9 -> #NAME? | AF9: =AE9/$AI$1+1 -> #NAME? | AG9: =(AF9/AF8-1)-中国_中债国债到期收益率_1年!H9%/252 -> #NAME? | AH9: =MIN((AF9-MAX($AF$3:AF9))/MAX($AF$3:AF9),0) -> #NAME?
A10: 44726 | B10: 20 | C10: 30 | D10: 30 | F10: =SUM(B10:E10) -> 80 | G10: =B10 -> 20 | H10: =5*C10 -> 150 | I10: =9*D10 -> 270 | J10: =16*E10 -> 0 | K10: =SUM(G10:J10) -> 440 | L10: =G10*Return!B10*100 -> 5 | M10: =H10*Return!C10*100 -> -328.5 | N10: =I10*Return!D10*100 -> -340.2 | O10: =J10*Return!E10*100 -> 0 | P10: =SUM(L10:O10) -> -663.7 | Q10: =SUM($P$3:P10) -> #NAME? | R10: =B10*中国_中债国债到期收益率_1年!B9/365*100 -> 10.973151 | S10: =C10*中国_中债国债到期收益率_1年!C9/365*100 -> 21.286849 | T10: =D10*中国_中债国债到期收益率_1年!D9/365*100 -> 22.727671 | U10: =E10*中国_中债国债到期收益率_1年!E9/365*100 -> 0 | V10: =SUM(R10:U10) -> 54.987671 | W10: =SUM($V$3:V10) -> #NAME? | X10: =MAX(F10-50,0)*中国_中债国债到期收益率_1年!H10*100/365 -> 13.39726 | Y10: =SUM($X$3:X10) -> 54.082192 | AB10: =Z10*Return!F10*100 -> 0 | AD10: =SUM($AB$3:AB10)+SUM($AC$3:AC10) -> 0 | AE10: =Q10+W10+AD10-Y10 -> #NAME? | AF10: =AE10/$AI$1+1 -> #NAME? | AG10: =(AF10/AF9-1)-中国_中债国债到期收益率_1年!H10%/252 -> #NAME? | AH10: =MIN((AF10-MAX($AF$3:AF10))/MAX($AF$3:AF10),0) -> #NAME?
A11: 44727 | B11: 30 | C11: 30 | D11: 30 | F11: =SUM(B11:E11) -> 90 | G11: =B11 -> 30 | H11: =5*C11 -> 150 | I11: =9*D11 -> 270 | J11: =16*E11 -> 0 | K11: =SUM(G11:J11) -> 450 | L11: =G11*Return!B11*100 -> -45 | M11: =H11*Return!C11*100 -> -79.5 | N11: =I11*Return!D11*100 -> -135 | O11: =J11*Return!E11*100 -> 0 | P11: =SUM(L11:O11) -> -259.5 | Q11: =SUM($P$3:P11) -> #NAME? | R11: =B11*中国_中债国债到期收益率_1年!B10/365*100 -> 16.583014 | S11: =C11*中国_中债国债到期收益率_1年!C10/365*100 -> 21.330411 | T11: =D11*中国_中债国债到期收益率_1年!D10/365*100 -> 22.768767 | U11: =E11*中国_中债国债到期收益率_1年!E10/365*100 -> 0 | V11: =SUM(R11:U11) -> 60.682192 | W11: =SUM($V$3:V11) -> #NAME? | X11: =MAX(F11-50,0)*中国_中债国债到期收益率_1年!H11*100/365 -> 17.863014 | Y11: =SUM($X$3:X11) -> 71.945205 | AB11: =Z11*Return!F11*100 -> 0 | AD11: =SUM($AB$3:AB11)+SUM($AC$3:AC11) -> 0 | AE11: =Q11+W11+AD11-Y11 -> #NAME? | AF11: =AE11/$AI$1+1 -> #NAME? | AG11: =(AF11/AF10-1)-中国_中债国债到期收益率_1年!H11%/252 -> #NAME? | AH11: =MIN((AF11-MAX($AF$3:AF11))/MAX($AF$3:AF11),0) -> #NAME?
A12: 44728 | B12: 30 | C12: 30 | D12: 30 | F12: =SUM(B12:E12) -> 90 | G12: =B12 -> 30 | H12: =5*C12 -> 150 | I12: =9*D12 -> 270 | J12: =16*E12 -> 0 | K12: =SUM(G12:J12) -> 450 | L12: =G12*Return!B12*100 -> -55.2 | M12: =H12*Return!C12*100 -> -240 | N12: =I12*Return!D12*100 -> -337.5 | O12: =J12*Return!E12*100 -> 0 | P12: =SUM(L12:O12) -> -632.7 | Q12: =SUM($P$3:P12) -> #NAME? | R12: =B12*中国_中债国债到期收益率_1年!B11/365*100 -> 16.734247 | S12: =C12*中国_中债国债到期收益率_1年!C11/365*100 -> 21.461918 | T12: =D12*中国_中债国债到期收益率_1年!D11/365*100 -> 22.871507 | U12: =E12*中国_中债国债到期收益率_1年!E11/365*100 -> 0 | V12: =SUM(R12:U12) -> 61.067671 | W12: =SUM($V$3:V12) -> #NAME? | X12: =MAX(F12-50,0)*中国_中债国债到期收益率_1年!H12*100/365 -> 18.082192 | Y12: =SUM($X$3:X12) -> 90.027397 | AB12: =Z12*Return!F12*100 -> 0 | AD12: =SUM($AB$3:AB12)+SUM($AC$3:AC12) -> 0 | AE12: =Q12+W12+AD12-Y12 -> #NAME? | AF12: =AE12/$AI$1+1 -> #NAME? | AG12: =(AF12/AF11-1)-中国_中债国债到期收益率_1年!H12%/252 -> #NAME? | AH12: =MIN((AF12-MAX($AF$3:AF12))/MAX($AF$3:AF12),0) -> #NAME?
A13: 44729 | B13: 30 | C13: 30 | D13: 30 | F13: =SUM(B13:E13) -> 90 | G13: =B13 -> 30 | H13: =5*C13 -> 150 | I13: =9*D13 -> 270 | J13: =16*E13 -> 0 | K13: =SUM(G13:J13) -> 450 | L13: =G13*Return!B13*100 -> 2.4 | M13: =H13*Return!C13*100 -> 264 | N13: =I13*Return!D13*100 -> 267.3 | O13: =J13*Return!E13*100 -> 0 | P13: =SUM(L13:O13) -> 533.7 | Q13: =SUM($P$3:P13) -> #NAME? | R13: =B13*中国_中债国债到期收益率_1年!B12/365*100 -> 16.727671 | S13: =C13*中国_中债国债到期收益率_1年!C12/365*100 -> 21.31726 | T13: =D13*中国_中债国债到期收益率_1年!D12/365*100 -> 22.790137 | U13: =E13*中国_中债国债到期收益率_1年!E12/365*100 -> 0 | V13: =SUM(R13:U13) -> 60.835068 | W13: =SUM($V$3:V13) -> #NAME? | X13: =MAX(F13-50,0)*中国_中债国债到期收益率_1年!H13*100/365 -> 18.630137 | Y13: =SUM($X$3:X13) -> 108.65753 | AB13: =Z13*Return!F13*100 -> 0 | AD13: =SUM($AB$3:AB13)+SUM($AC$3:AC13) -> 0 | AE13: =Q13+W13+AD13-Y13 -> #NAME? | AF13: =AE13/$AI$1+1 -> #NAME? | AG13: =(AF13/AF12-1)-中国_中债国债到期收益率_1年!H13%/252 -> #NAME? | AH13: =MIN((AF13-MAX($AF$3:AF13))/MAX($AF$3:AF13),0) -> #NAME?
A14: 44732 | B14: 30 | C14: 30 | D14: 30 | F14: =SUM(B14:E14) -> 90 | G14: =B14 -> 30 | H14: =5*C14 -> 150 | I14: =9*D14 -> 270 | J14: =16*E14 -> 0 | K14: =SUM(G14:J14) -> 450 | L14: =G14*Return!B14*100 -> 75 | M14: =H14*Return!C14*100 -> -12 | N14: =I14*Return!D14*100 -> -64.8 | O14: =J14*Return!E14*100 -> 0 | P14: =SUM(L14:O14) -> -1.8 | Q14: =SUM($P$3:P14) -> #NAME? | R14: =B14*中国_中债国债到期收益率_1年!B13/365*100 -> 16.522192 | S14: =C14*中国_中债国债到期收益率_1年!C13/365*100 -> 21.323836 | T14: =D14*中国_中债国债到期收益率_1年!D13/365*100 -> 22.809863 | U14: =E14*中国_中债国债到期收益率_1年!E13/365*100 -> 0 | V14: =SUM(R14:U14) -> 60.65589 | W14: =SUM($V$3:V14) -> #NAME? | X14: =MAX(F14-50,0)*中国_中债国债到期收益率_1年!H14*100/365 -> 18.630137 | Y14: =SUM($X$3:X14) -> 127.28767 | AB14: =Z14*Return!F14*100 -> 0 | AD14: =SUM($AB$3:AB14)+SUM($AC$3:AC14) -> 0 | AE14: =Q14+W14+AD14-Y14 -> #NAME? | AF14: =AE14/$AI$1+1 -> #NAME? | AG14: =(AF14/AF13-1)-中国_中债国债到期收益率_1年!H14%/252 -> #NAME? | AH14: =MIN((AF14-MAX($AF$3:AF14))/MAX($AF$3:AF14),0) -> #NAME?
A15: 44733 | B15: 30 | C15: 30 | D15: 30 | F15: =SUM(B15:E15) -> 90 | G15: =B15 -> 30 | H15: =5*C15 -> 150 | I15: =9*D15 -> 270 | J15: =16*E15 -> 0 | K15: =SUM(G15:J15) -> 450 | L15: =G15*Return!B15*100 -> 13.8 | M15: =H15*Return!C15*100 -> -328.5 | N15: =I15*Return!D15*100 -> -272.7 | O15: =J15*Return!E15*100 -> 0 | P15: =SUM(L15:O15) -> -587.4 | Q15: =SUM($P$3:P15) -> #NAME? | R15: =B15*中国_中债国债到期收益率_1年!B14/365*100 -> 16.484384 | S15: =C15*中国_中债国债到期收益率_1年!C14/365*100 -> 21.503836 | T15: =D15*中国_中债国债到期收益率_1年!D14/365*100 -> 22.892877 | U15: =E15*中国_中债国债到期收益率_1年!E14/365*100 -> 0 | V15: =SUM(R15:U15) -> 60.881096 | W15: =SUM($V$3:V15) -> #NAME? | X15: =MAX(F15-50,0)*中国_中债国债到期收益率_1年!H15*100/365 -> 19.178082 | Y15: =SUM($X$3:X15) -> 146.46575 | AB15: =Z15*Return!F15*100 -> 0 | AD15: =SUM($AB$3:AB15)+SUM($AC$3:AC15) -> 0 | AE15: =Q15+W15+AD15-Y15 -> #NAME? | AF15: =AE15/$AI$1+1 -> #NAME? | AG15: =(AF15/AF14-1)-中国_中债国债到期收益率_1年!H15%/252 -> #NAME? | AH15: =MIN((AF15-MAX($AF$3:AF15))/MAX($AF$3:AF15),0) -> #NAME?
... A23: 44743 | B23: 30 | C23: 30 | D23: 20 | F23: =SUM(B23:E23) -> 80 | G23: =B23 -> 30 | H23: =5*C23 -> 150 | I23: =9*D23 -> 180 | J23: =16*E23 -> 0 | K23: =SUM(G23:J23) -> 360 | L23: =G23*Return!B23*100 -> 77.7 | M23: =H23*Return!C23*100 -> 304.5 | N23: =I23*Return!D23*100 -> 160.2 | O23: =J23*Return!E23*100 -> 0 | P23: =SUM(L23:O23) -> 542.4 | Q23: =SUM($P$3:P23) -> #NAME? | R23: =B23*中国_中债国债到期收益率_1年!B22/365*100 -> 16.030685 | S23: =C23*中国_中债国债到期收益率_1年!C22/365*100 -> 21.804658 | T23: =D23*中国_中债国债到期收益率_1年!D22/365*100 -> 15.454795 | U23: =E23*中国_中债国债到期收益率_1年!E22/365*100 -> 0 | V23: =SUM(R23:U23) -> 53.290137 | W23: =SUM($V$3:V23) -> #NAME? | X23: =MAX(F23-50,0)*中国_中债国债到期收益率_1年!H23*100/365 -> 14.383562 | Y23: =SUM($X$3:X23) -> 328.1074 | AB23: =Z23*Return!F23*100 -> 0 | AD23: =SUM($AB$3:AB23)+SUM($AC$3:AC23) -> 0 | AE23: =Q23+W23+AD23-Y23 -> #NAME? | AF23: =AE23/$AI$1+1 -> #NAME? | AG23: =(AF23/AF22-1)-中国_中债国债到期收益率_1年!H23%/252 -> #NAME? | AH23: =MIN((AF23-MAX($AF$3:AF23))/MAX($AF$3:AF23),0) -> #NAME?
A24: 44746 | B24: 30 | C24: 30 | D24: 20 | E24: 5 | F24: =SUM(B24:E24) -> 85 | G24: =B24 -> 30 | H24: =5*C24 -> 150 | I24: =9*D24 -> 180 | J24: =16*E24 -> 80 | K24: =SUM(G24:J24) -> 440 | L24: =G24*Return!B24*100 -> 54 | M24: =H24*Return!C24*100 -> 66 | N24: =I24*Return!D24*100 -> -90 | O24: =J24*Return!E24*100 -> -20.8 | P24: =SUM(L24:O24) -> 9.2 | Q24: =SUM($P$3:P24) -> #NAME? | R24: =B24*中国_中债国债到期收益率_1年!B23/365*100 -> 15.88274 | S24: =C24*中国_中债国债到期收益率_1年!C23/365*100 -> 21.768493 | T24: =D24*中国_中债国债到期收益率_1年!D23/365*100 -> 15.482192 | U24: =E24*中国_中债国债到期收益率_1年!E23/365*100 -> 4.510411 | V24: =SUM(R24:U24) -> 57.643836 | W24: =SUM($V$3:V24) -> #NAME? | X24: =MAX(F24-50,0)*中国_中债国债到期收益率_1年!H24*100/365 -> 15.342466 | Y24: =SUM($X$3:X24) -> 343.44986 | AB24: =Z24*Return!F24*100 -> 0 | AD24: =SUM($AB$3:AB24)+SUM($AC$3:AC24) -> 0 | AE24: =Q24+W24+AD24-Y24 -> #NAME? | AF24: =AE24/$AI$1+1 -> #NAME? | AG24: =(AF24/AF23-1)-中国_中债国债到期收益率_1年!H24%/252 -> #NAME? | AH24: =MIN((AF24-MAX($AF$3:AF24))/MAX($AF$3:AF24),0) -> #NAME?
A25: 44747 | B25: 30 | C25: 30 | D25: 20 | E25: 5 | F25: =SUM(B25:E25) -> 85 | G25: =B25 -> 30 | H25: =5*C25 -> 150 | I25: =9*D25 -> 180 | J25: =16*E25 -> 80 | K25: =SUM(G25:J25) -> 440 | L25: =G25*Return!B25*100 -> -152.1 | M25: =H25*Return!C25*100 -> -720 | N25: =I25*Return!D25*100 -> -342 | O25: =J25*Return!E25*100 -> -140 | P25: =SUM(L25:O25) -> -1354.1 | Q25: =SUM($P$3:P25) -> #NAME? | R25: =B25*中国_中债国债到期收益率_1年!B24/365*100 -> 16.299452 | S25: =C25*中国_中债国债到期收益率_1年!C24/365*100 -> 22.163014 | T25: =D25*中国_中债国债到期收益率_1年!D24/365*100 -> 15.586301 | U25: =E25*中国_中债国债到期收益率_1年!E24/365*100 -> 4.5343836 | V25: =SUM(R25:U25) -> 58.583151 | W25: =SUM($V$3:V25) -> #NAME? | X25: =MAX(F25-50,0)*中国_中债国债到期收益率_1年!H25*100/365 -> 16.30137 | Y25: =SUM($X$3:X25) -> 359.75123 | AB25: =Z25*Return!F25*100 -> 0 | AD25: =SUM($AB$3:AB25)+SUM($AC$3:AC25) -> 0 | AE25: =Q25+W25+AD25-Y25 -> #NAME? | AF25: =AE25/$AI$1+1 -> #NAME? | AG25: =(AF25/AF24-1)-中国_中债国债到期收益率_1年!H25%/252 -> #NAME? | AH25: =MIN((AF25-MAX($AF$3:AF25))/MAX($AF$3:AF25),0) -> #NAME?
A26: 44748 | B26: 30 | C26: 30 | D26: 20 | E26: 5 | F26: =SUM(B26:E26) -> 85 | G26: =B26 -> 30 | H26: =5*C26 -> 150 | I26: =9*D26 -> 180 | J26: =16*E26 -> 80 | K26: =SUM(G26:J26) -> 440 | L26: =G26*Return!B26*100 -> -80.7 | M26: =H26*Return!C26*100 -> 52.5 | N26: =I26*Return!D26*100 -> 201.6 | O26: =J26*Return!E26*100 -> -41.6 | P26: =SUM(L26:O26) -> 131.8 | Q26: =SUM($P$3:P26) -> #NAME? | R26: =B26*中国_中债国债到期收益率_1年!B25/365*100 -> 16.520548 | S26: =C26*中国_中债国债到期收益率_1年!C25/365*100 -> 22.134247 | T26: =D26*中国_中债国债到期收益率_1年!D25/365*100 -> 15.524932 | U26: =E26*中国_中债国债到期收益率_1年!E25/365*100 -> 4.5415068 | V26: =SUM(R26:U26) -> 58.721233 | W26: =SUM($V$3:V26) -> #NAME? | X26: =MAX(F26-50,0)*中国_中债国债到期收益率_1年!H26*100/365 -> 16.30137 | Y26: =SUM($X$3:X26) -> 376.0526 | AB26: =Z26*Return!F26*100 -> 0 | AD26: =SUM($AB$3:AB26)+SUM($AC$3:AC26) -> 0 | AE26: =Q26+W26+AD26-Y26 -> #NAME? | AF26: =AE26/$AI$1+1 -> #NAME? | AG26: =(AF26/AF25-1)-中国_中债国债到期收益率_1年!H26%/252 -> #NAME? | AH26: =MIN((AF26-MAX($AF$3:AF26))/MAX($AF$3:AF26),0) -> #NAME?
A27: 44749 | B27: 30 | C27: 30 | D27: 20 | E27: 5 | F27: =SUM(B27:E27) -> 85 | G27: =B27 -> 30 | H27: =5*C27 -> 150 | I27: =9*D27 -> 180 | J27: =16*E27 -> 80 | K27: =SUM(G27:J27) -> 440 | L27: =G27*Return!B27*100 -> 56.7 | M27: =H27*Return!C27*100 -> 42 | N27: =I27*Return!D27*100 -> -41.4 | O27: =J27*Return!E27*100 -> 0 | P27: =SUM(L27:O27) -> 57.3 | Q27: =SUM($P$3:P27) -> #NAME? | R27: =B27*中国_中债国债到期收益率_1年!B26/365*100 -> 16.365205 | S27: =C27*中国_中债国债到期收益率_1年!C26/365*100 -> 22.111233 | T27: =D27*中国_中债国债到期收益率_1年!D26/365*100 -> 15.537534 | U27: =E27*中国_中债国债到期收益率_1年!E26/365*100 -> 4.5415068 | V27: =SUM(R27:U27) -> 58.555479 | W27: =SUM($V$3:V27) -> #NAME? | X27: =MAX(F27-50,0)*中国_中债国债到期收益率_1年!H27*100/365 -> 15.821918 | Y27: =SUM($X$3:X27) -> 391.87452 | AB27: =Z27*Return!F27*100 -> 0 | AD27: =SUM($AB$3:AB27)+SUM($AC$3:AC27) -> 0 | AE27: =Q27+W27+AD27-Y27 -> #NAME? | AF27: =AE27/$AI$1+1 -> #NAME? | AG27: =(AF27/AF26-1)-中国_中债国债到期收益率_1年!H27%/252 -> #NAME? | AH27: =MIN((AF27-MAX($AF$3:AF27))/MAX($AF$3:AF27),0) -> #NAME?
A28: 44750 | B28: 30 | C28: 30 | D28: 20 | E28: 5 | F28: =SUM(B28:E28) -> 85 | G28: =B28 -> 30 | H28: =5*C28 -> 150 | I28: =9*D28 -> 180 | J28: =16*E28 -> 80 | K28: =SUM(G28:J28) -> 440 | L28: =G28*Return!B28*100 -> 26.1 | M28: =H28*Return!C28*100 -> 67.5 | N28: =I28*Return!D28*100 -> 0 | O28: =J28*Return!E28*100 -> -0.8 | P28: =SUM(L28:O28) -> 92.8 | Q28: =SUM($P$3:P28) -> #NAME? | R28: =B28*中国_中债国债到期收益率_1年!B27/365*100 -> 16.293699 | S28: =C28*中国_中债国债到期收益率_1年!C27/365*100 -> 22.074247 | T28: =D28*中国_中债国债到期收益率_1年!D27/365*100 -> 15.537534 | U28: =E28*中国_中债国债到期收益率_1年!E27/365*100 -> 4.5416438 | V28: =SUM(R28:U28) -> 58.447123 | W28: =SUM($V$3:V28) -> #NAME? | X28: =MAX(F28-50,0)*中国_中债国债到期收益率_1年!H28*100/365 -> 15.342466 | Y28: =SUM($X$3:X28) -> 407.21699 | AB28: =Z28*Return!F28*100 -> 0 | AD28: =SUM($AB$3:AB28)+SUM($AC$3:AC28) -> 0 | AE28: =Q28+W28+AD28-Y28 -> #NAME? | AF28: =AE28/$AI$1+1 -> #NAME? | AG28: =(AF28/AF27-1)-中国_中债国债到期收益率_1年!H28%/252 -> #NAME? | AH28: =MIN((AF28-MAX($AF$3:AF28))/MAX($AF$3:AF28),0) -> #NAME?
A29: 44753 | B29: 30 | C29: 30 | D29: 20 | E29: 5 | F29: =SUM(B29:E29) -> 85 | G29: =B29 -> 30 | H29: =5*C29 -> 150 | I29: =9*D29 -> 180 | J29: =16*E29 -> 80 | K29: =SUM(G29:J29) -> 440 | L29: =G29*Return!B29*100 -> 72 | M29: =H29*Return!C29*100 -> 108 | N29: =I29*Return!D29*100 -> -50.4 | O29: =J29*Return!E29*100 -> -202.4 | P29: =SUM(L29:O29) -> -72.8 | Q29: =SUM($P$3:P29) -> #NAME? | R29: =B29*中国_中债国债到期收益率_1年!B28/365*100 -> 16.096438 | S29: =C29*中国_中债国债到期收益率_1年!C28/365*100 -> 22.015068 | T29: =D29*中国_中债国债到期收益率_1年!D28/365*100 -> 15.552877 | U29: =E29*中国_中债国债到期收益率_1年!E28/365*100 -> 4.5763014 | V29: =SUM(R29:U29) -> 58.240685 | W29: =SUM($V$3:V29) -> #NAME? | X29: =MAX(F29-50,0)*中国_中债国债到期收益率_1年!H29*100/365 -> 15.342466 | Y29: =SUM($X$3:X29) -> 422.55945 | AB29: =Z29*Return!F29*100 -> 0 | AD29: =SUM($AB$3:AB29)+SUM($AC$3:AC29) -> 0 | AE29: =Q29+W29+AD29-Y29 -> #NAME? | AF29: =AE29/$AI$1+1 -> #NAME? | AG29: =(AF29/AF28-1)-中国_中债国债到期收益率_1年!H29%/252 -> #NAME? | AH29: =MIN((AF29-MAX($AF$3:AF29))/MAX($AF$3:AF29),0) -> #NAME?
A30: 44754 | B30: 30 | C30: 30 | D30: 20 | E30: 5 | F30: =SUM(B30:E30) -> 85 | G30: =B30 -> 30 | H30: =5*C30 -> 150 | I30: =9*D30 -> 180 | J30: =16*E30 -> 80 | K30: =SUM(G30:J30) -> 440 | L30: =G30*Return!B30*100 -> 50.1 | M30: =H30*Return!C30*100 -> 375 | N30: =I30*Return!D30*100 -> 212.4 | O30: =J30*Return!E30*100 -> 66.4 | P30: =SUM(L30:O30) -> 703.9 | Q30: =SUM($P$3:P30) -> #NAME? | R30: =B30*中国_中债国债到期收益率_1年!B29/365*100 -> 15.959178 | S30: =C30*中国_中债国债到期收益率_1年!C29/365*100 -> 21.809589 | T30: =D30*中国_中债国债到期收益率_1年!D29/365*100 -> 15.488219 | U30: =E30*中国_中债国债到期收益率_1年!E29/365*100 -> 4.5649315 | V30: =SUM(R30:U30) -> 57.821918 | W30: =SUM($V$3:V30) -> #NAME? | X30: =MAX(F30-50,0)*中国_中债国债到期收益率_1年!H30*100/365 -> 15.342466 | Y30: =SUM($X$3:X30) -> 437.90192 | AB30: =Z30*Return!F30*100 -> 0 | AD30: =SUM($AB$3:AB30)+SUM($AC$3:AC30) -> 0 | AE30: =Q30+W30+AD30-Y30 -> #NAME? | AF30: =AE30/$AI$1+1 -> #NAME? | AG30: =(AF30/AF29-1)-中国_中债国债到期收益率_1年!H30%/252 -> #NAME? | AH30: =MIN((AF30-MAX($AF$3:AF30))/MAX($AF$3:AF30),0) -> #NAME?
A31: 44755 | B31: 30 | C31: 30 | D31: 20 | E31: 5 | F31: =SUM(B31:E31) -> 85 | G31: =B31 -> 30 | H31: =5*C31 -> 150 | I31: =9*D31 -> 180 | J31: =16*E31 -> 80 | K31: =SUM(G31:J31) -> 440 | L31: =G31*Return!B31*100 -> 21.6 | M31: =H31*Return!C31*100 -> 489 | N31: =I31*Return!D31*100 -> 268.2 | O31: =J31*Return!E31*100 -> 112 | P31: =SUM(L31:O31) -> 890.8 | Q31: =SUM($P$3:P31) -> #NAME? | R31: =B31*中国_中债国债到期收益率_1年!B30/365*100 -> 15.9 | S31: =C31*中国_中债国债到期收益率_1年!C30/365*100 -> 21.541644 | T31: =D31*中国_中债国债到期收益率_1年!D30/365*100 -> 15.406575 | U31: =E31*中国_中债国债到期收益率_1年!E30/365*100 -> 4.5457534 | V31: =SUM(R31:U31) -> 57.393973 | W31: =SUM($V$3:V31) -> #NAME? | X31: =MAX(F31-50,0)*中国_中债国债到期收益率_1年!H31*100/365 -> 15.246575 | Y31: =SUM($X$3:X31) -> 453.14849 | AB31: =Z31*Return!F31*100 -> 0 | AD31: =SUM($AB$3:AB31)+SUM($AC$3:AC31) -> 0 | AE31: =Q31+W31+AD31-Y31 -> #NAME? | AF31: =AE31/$AI$1+1 -> #NAME? | AG31: =(AF31/AF30-1)-中国_中债国债到期收益率_1年!H31%/252 -> #NAME? | AH31: =MIN((AF31-MAX($AF$3:AF31))/MAX($AF$3:AF31),0) -> #NAME?
A32: 44756 | B32: 30 | C32: 30 | D32: 20 | E32: 5 | F32: =SUM(B32:E32) -> 85 | G32: =B32 -> 30 | H32: =5*C32 -> 150 | I32: =9*D32 -> 180 | J32: =16*E32 -> 80 | K32: =SUM(G32:J32) -> 440 | L32: =G32*Return!B32*100 -> -9.3 | M32: =H32*Return!C32*100 -> 112.5 | N32: =I32*Return!D32*100 -> 90 | O32: =J32*Return!E32*100 -> 19.2 | P32: =SUM(L32:O32) -> 212.4 | Q32: =SUM($P$3:P32) -> #NAME? | R32: =B32*中国_中债国债到期收益率_1年!B31/365*100 -> 15.925479 | S32: =C32*中国_中债国债到期收益率_1年!C31/365*100 -> 21.48 | T32: =D32*中国_中债国债到期收益率_1年!D31/365*100 -> 15.379178 | U32: =E32*中国_中债国债到期收益率_1年!E31/365*100 -> 4.5424658 | V32: =SUM(R32:U32) -> 57.327123 | W32: =SUM($V$3:V32) -> #NAME? | X32: =MAX(F32-50,0)*中国_中债国债到期收益率_1年!H32*100/365 -> 15.342466 | Y32: =SUM($X$3:X32) -> 468.49096 | AB32: =Z32*Return!F32*100 -> 0 | AD32: =SUM($AB$3:AB32)+SUM($AC$3:AC32) -> 0 | AE32: =Q32+W32+AD32-Y32 -> #NAME? | AF32: =AE32/$AI$1+1 -> #NAME? | AG32: =(AF32/AF31-1)-中国_中债国债到期收益率_1年!H32%/252 -> #NAME? | AH32: =MIN((AF32-MAX($AF$3:AF32))/MAX($AF$3:AF32),0) -> #NAME?
A33: 44757 | B33: 30 | C33: 30 | D33: 20 | E33: 5 | F33: =SUM(B33:E33) -> 85 | G33: =B33 -> 30 | H33: =5*C33 -> 150 | I33: =9*D33 -> 180 | J33: =16*E33 -> 80 | K33: =SUM(G33:J33) -> 440 | L33: =G33*Return!B33*100 -> 68.7 | M33: =H33*Return!C33*100 -> 396 | N33: =I33*Return!D33*100 -> 288 | O33: =J33*Return!E33*100 -> 160 | P33: =SUM(L33:O33) -> 912.7 | Q33: =SUM($P$3:P33) -> #NAME? | R33: =B33*中国_中债国债到期收益率_1年!B32/365*100 -> 15.73726 | S33: =C33*中国_中债国债到期收益率_1年!C32/365*100 -> 21.263014 | T33: =D33*中国_中债国债到期收益率_1年!D32/365*100 -> 15.291507 | U33: =E33*中国_中债国债到期收益率_1年!E32/365*100 -> 4.5150685 | V33: =SUM(R33:U33) -> 56.806849 | W33: =SUM($V$3:V33) -> #NAME? | X33: =MAX(F33-50,0)*中国_中债国债到期收益率_1年!H33*100/365 -> 15.054795 | Y33: =SUM($X$3:X33) -> 483.54575 | AB33: =Z33*Return!F33*100 -> 0 | AD33: =SUM($AB$3:AB33)+SUM($AC$3:AC33) -> 0 | AE33: =Q33+W33+AD33-Y33 -> #NAME? | AF33: =AE33/$AI$1+1 -> #NAME? | AG33: =(AF33/AF32-1)-中国_中债国债到期收益率_1年!H33%/252 -> #NAME? | AH33: =MIN((AF33-MAX($AF$3:AF33))/MAX($AF$3:AF33),0) -> #NAME?
A34: 44760 | B34: 30 | C34: 30 | D34: 20 | E34: 5 | F34: =SUM(B34:E34) -> 85 | G34: =B34 -> 30 | H34: =5*C34 -> 150 | I34: =9*D34 -> 180 | J34: =16*E34 -> 80 | K34: =SUM(G34:J34) -> 440 | L34: =G34*Return!B34*100 -> 93 | M34: =H34*Return!C34*100 -> 33 | N34: =I34*Return!D34*100 -> 90 | O34: =J34*Return!E34*100 -> 80.8 | P34: =SUM(L34:O34) -> 296.8 | Q34: =SUM($P$3:P34) -> #NAME? | R34: =B34*中国_中债国债到期收益率_1年!B33/365*100 -> 15.482466 | S34: =C34*中国_中债国债到期收益率_1年!C33/365*100 -> 21.244932 | T34: =D34*中国_中债国债到期收益率_1年!D33/365*100 -> 15.26411 | U34: =E34*中国_中债国债到期收益率_1年!E33/365*100 -> 4.5012329 | V34: =SUM(R34:U34) -> 56.49274 | W34: =SUM($V$3:V34) -> #NAME? | X34: =MAX(F34-50,0)*中国_中债国债到期收益率_1年!H34*100/365 -> 15.441233 | Y34: =SUM($X$3:X34) -> 498.98699 | AB34: =Z34*Return!F34*100 -> 0 | AD34: =SUM($AB$3:AB34)+SUM($AC$3:AC34) -> 0 | AE34: =Q34+W34+AD34-Y34 -> #NAME? | AF34: =AE34/$AI$1+1 -> #NAME? | AG34: =(AF34/AF33-1)-中国_中债国债到期收益率_1年!H34%/252 -> #NAME? | AH34: =MIN((AF34-MAX($AF$3:AF34))/MAX($AF$3:AF34),0) -> #NAME?
A35: 44761 | B35: 30 | C35: 30 | D35: 20 | E35: 5 | F35: =SUM(B35:E35) -> 85 | G35: =B35 -> 30 | H35: =5*C35 -> 150 | I35: =9*D35 -> 180 | J35: =16*E35 -> 80 | K35: =SUM(G35:J35) -> 440 | L35: =G35*Return!B35*100 -> 104.7 | M35: =H35*Return!C35*100 -> 88.5 | N35: =I35*Return!D35*100 -> 36 | O35: =J35*Return!E35*100 -> 59.2 | P35: =SUM(L35:O35) -> 288.4 | Q35: =SUM($P$3:P35) -> #NAME? | R35: =B35*中国_中债国债到期收益率_1年!B34/365*100 -> 15.195616 | S35: =C35*中国_中债国债到期收益率_1年!C34/365*100 -> 21.196438 | T35: =D35*中国_中债国债到期收益率_1年!D34/365*100 -> 15.253151 | U35: =E35*中国_中债国债到期收益率_1年!E34/365*100 -> 4.4910959 | V35: =SUM(R35:U35) -> 56.136301 | W35: =SUM($V$3:V35) -> #NAME? | X35: =MAX(F35-50,0)*中国_中债国债到期收益率_1年!H35*100/365 -> 15.342466 | Y35: =SUM($X$3:X35) -> 514.32945 | AB35: =Z35*Return!F35*100 -> 0 | AD35: =SUM($AB$3:AB35)+SUM($AC$3:AC35) -> 0 | AE35: =Q35+W35+AD35-Y35 -> #NAME? | AF35: =AE35/$AI$1+1 -> #NAME? | AG35: =(AF35/AF34-1)-中国_中债国债到期收益率_1年!H35%/252 -> #NAME? | AH35: =MIN((AF35-MAX($AF$3:AF35))/MAX($AF$3:AF35),0) -> #NAME?
... A58: 44792 | B58: 30 | C58: 30 | D58: 20 | E58: 5 | F58: =SUM(B58:E58) -> 85 | G58: =B58 -> 30 | H58: =5*C58 -> 150 | I58: =9*D58 -> 180 | J58: =16*E58 -> 80 | K58: =SUM(G58:J58) -> 440 | L58: =G58*Return!B58*100 -> 55.8 | M58: =H58*Return!C58*100 -> 334.5 | N58: =I58*Return!D58*100 -> 583.2 | O58: =J58*Return!E58*100 -> 264.8 | P58: =SUM(L58:O58) -> 1238.3 | Q58: =SUM($P$3:P58) -> #NAME? | R58: =B58*中国_中债国债到期收益率_1年!B57/365*100 -> 13.97589 | S58: =C58*中国_中债国债到期收益率_1年!C57/365*100 -> 19.379178 | T58: =D58*中国_中债国债到期收益率_1年!D57/365*100 -> 14.136986 | U58: =E58*中国_中债国债到期收益率_1年!E57/365*100 -> 4.2983562 | V58: =SUM(R58:U58) -> 51.790411 | W58: =SUM($V$3:V58) -> #NAME? | X58: =MAX(F58-50,0)*中国_中债国债到期收益率_1年!H58*100/365 -> 14.383562 | Y58: =SUM($X$3:X58) -> 849.02247 | AB58: =Z58*Return!F58*100 -> 0 | AD58: =SUM($AB$3:AB58)+SUM($AC$3:AC58) -> 0 | AE58: =Q58+W58+AD58-Y58 -> #NAME? | AF58: =AE58/$AI$1+1 -> #NAME? | AG58: =(AF58/AF57-1)-中国_中债国债到期收益率_1年!H58%/252 -> #NAME? | AH58: =MIN((AF58-MAX($AF$3:AF58))/MAX($AF$3:AF58),0) -> #NAME?
A59: 44795 | B59: 30 | C59: 30 | D59: 20 | F59: =SUM(B59:E59) -> 80 | G59: =B59 -> 30 | H59: =5*C59 -> 150 | I59: =9*D59 -> 180 | J59: =16*E59 -> 0 | K59: =SUM(G59:J59) -> 360 | L59: =G59*Return!B59*100 -> -73.2 | M59: =H59*Return!C59*100 -> -195 | N59: =I59*Return!D59*100 -> -135 | O59: =J59*Return!E59*100 -> 0 | P59: =SUM(L59:O59) -> -403.2 | Q59: =SUM($P$3:P59) -> #NAME? | R59: =B59*中国_中债国债到期收益率_1年!B58/365*100 -> 14.176438 | S59: =C59*中国_中债国债到期收益率_1年!C58/365*100 -> 19.486027 | T59: =D59*中国_中债国债到期收益率_1年!D58/365*100 -> 14.178082 | U59: =E59*中国_中债国债到期收益率_1年!E58/365*100 -> 0 | V59: =SUM(R59:U59) -> 47.840548 | W59: =SUM($V$3:V59) -> #NAME? | X59: =MAX(F59-50,0)*中国_中债国债到期收益率_1年!H59*100/365 -> 12.328767 | Y59: =SUM($X$3:X59) -> 861.35123 | AB59: =Z59*Return!F59*100 -> 0 | AD59: =SUM($AB$3:AB59)+SUM($AC$3:AC59) -> 0 | AE59: =Q59+W59+AD59-Y59 -> #NAME? | AF59: =AE59/$AI$1+1 -> #NAME? | AG59: =(AF59/AF58-1)-中国_中债国债到期收益率_1年!H59%/252 -> #NAME? | AH59: =MIN((AF59-MAX($AF$3:AF59))/MAX($AF$3:AF59),0) -> #NAME?
A60: 44796 | B60: 30 | C60: 30 | D60: 20 | F60: =SUM(B60:E60) -> 80 | G60: =B60 -> 30 | H60: =5*C60 -> 150 | I60: =9*D60 -> 180 | J60: =16*E60 -> 0 | K60: =SUM(G60:J60) -> 360 | L60: =G60*Return!B60*100 -> -96.6 | M60: =H60*Return!C60*100 -> -388.5 | N60: =I60*Return!D60*100 -> -90 | O60: =J60*Return!E60*100 -> 0 | P60: =SUM(L60:O60) -> -575.1 | Q60: =SUM($P$3:P60) -> #NAME? | R60: =B60*中国_中债国债到期收益率_1年!B59/365*100 -> 14.441096 | S60: =C60*中国_中债国债到期收益率_1年!C59/365*100 -> 19.698904 | T60: =D60*中国_中债国债到期收益率_1年!D59/365*100 -> 14.205479 | U60: =E60*中国_中债国债到期收益率_1年!E59/365*100 -> 0 | V60: =SUM(R60:U60) -> 48.345479 | W60: =SUM($V$3:V60) -> #NAME? | X60: =MAX(F60-50,0)*中国_中债国债到期收益率_1年!H60*100/365 -> 11.917808 | Y60: =SUM($X$3:X60) -> 873.26904 | AB60: =Z60*Return!F60*100 -> 0 | AD60: =SUM($AB$3:AB60)+SUM($AC$3:AC60) -> 0 | AE60: =Q60+W60+AD60-Y60 -> #NAME? | AF60: =AE60/$AI$1+1 -> #NAME? | AG60: =(AF60/AF59-1)-中国_中债国债到期收益率_1年!H60%/252 -> #NAME? | AH60: =MIN((AF60-MAX($AF$3:AF60))/MAX($AF$3:AF60),0) -> #NAME?
A61: 44797 | B61: 30 | C61: 30 | D61: 20 | F61: =SUM(B61:E61) -> 80 | G61: =B61 -> 30 | H61: =5*C61 -> 150 | I61: =9*D61 -> 180 | J61: =16*E61 -> 0 | K61: =SUM(G61:J61) -> 360 | L61: =G61*Return!B61*100 -> -0.3 | M61: =H61*Return!C61*100 -> -186 | N61: =I61*Return!D61*100 -> -270 | O61: =J61*Return!E61*100 -> 0 | P61: =SUM(L61:O61) -> -456.3 | Q61: =SUM($P$3:P61) -> #NAME? | R61: =B61*中国_中债国债到期收益率_1年!B60/365*100 -> 14.441918 | S61: =C61*中国_中债国债到期收益率_1年!C60/365*100 -> 19.800822 | T61: =D61*中国_中债国债到期收益率_1年!D60/365*100 -> 14.287671 | U61: =E61*中国_中债国债到期收益率_1年!E60/365*100 -> 0 | V61: =SUM(R61:U61) -> 48.530411 | W61: =SUM($V$3:V61) -> #NAME? | X61: =MAX(F61-50,0)*中国_中债国债到期收益率_1年!H61*100/365 -> 11.917808 | Y61: =SUM($X$3:X61) -> 885.18685 | AB61: =Z61*Return!F61*100 -> 0 | AD61: =SUM($AB$3:AB61)+SUM($AC$3:AC61) -> 0 | AE61: =Q61+W61+AD61-Y61 -> #NAME? | AF61: =AE61/$AI$1+1 -> #NAME? | AG61: =(AF61/AF60-1)-中国_中债国债到期收益率_1年!H61%/252 -> #NAME? | AH61: =MIN((AF61-MAX($AF$3:AF61))/MAX($AF$3:AF61),0) -> #NAME?
A62: 44798 | B62: 30 | C62: 30 | D62: 20 | F62: =SUM(B62:E62) -> 80 | G62: =B62 -> 30 | H62: =5*C62 -> 150 | I62: =9*D62 -> 180 | J62: =16*E62 -> 0 | K62: =SUM(G62:J62) -> 360 | L62: =G62*Return!B62*100 -> 22.5 | M62: =H62*Return!C62*100 -> -46.5 | N62: =I62*Return!D62*100 -> -45 | O62: =J62*Return!E62*100 -> 0 | P62: =SUM(L62:O62) -> -69 | Q62: =SUM($P$3:P62) -> #NAME? | R62: =B62*中国_中债国债到期收益率_1年!B61/365*100 -> 14.380274 | S62: =C62*中国_中债国债到期收益率_1年!C61/365*100 -> 19.826301 | T62: =D62*中国_中债国债到期收益率_1年!D61/365*100 -> 14.30137 | U62: =E62*中国_中债国债到期收益率_1年!E61/365*100 -> 0 | V62: =SUM(R62:U62) -> 48.507945 | W62: =SUM($V$3:V62) -> #NAME? | X62: =MAX(F62-50,0)*中国_中债国债到期收益率_1年!H62*100/365 -> 13.972603 | Y62: =SUM($X$3:X62) -> 899.15945 | AB62: =Z62*Return!F62*100 -> 0 | AD62: =SUM($AB$3:AB62)+SUM($AC$3:AC62) -> 0 | AE62: =Q62+W62+AD62-Y62 -> #NAME? | AF62: =AE62/$AI$1+1 -> #NAME? | AG62: =(AF62/AF61-1)-中国_中债国债到期收益率_1年!H62%/252 -> #NAME? | AH62: =MIN((AF62-MAX($AF$3:AF62))/MAX($AF$3:AF62),0) -> #NAME?
A63: 44799 | B63: 30 | C63: 30 | D63: 20 | F63: =SUM(B63:E63) -> 80 | G63: =B63 -> 30 | H63: =5*C63 -> 150 | I63: =9*D63 -> 180 | J63: =16*E63 -> 0 | K63: =SUM(G63:J63) -> 360 | L63: =G63*Return!B63*100 -> -124.8 | M63: =H63*Return!C63*100 -> -489 | N63: =I63*Return!D63*100 -> -522 | O63: =J63*Return!E63*100 -> 0 | P63: =SUM(L63:O63) -> -1135.8 | Q63: =SUM($P$3:P63) -> #NAME? | R63: =B63*中国_中债国债到期收益率_1年!B62/365*100 -> 14.722192 | S63: =C63*中国_中债国债到期收益率_1年!C62/365*100 -> 20.094247 | T63: =D63*中国_中债国债到期收益率_1年!D62/365*100 -> 14.460274 | U63: =E63*中国_中债国债到期收益率_1年!E62/365*100 -> 0 | V63: =SUM(R63:U63) -> 49.276712 | W63: =SUM($V$3:V63) -> #NAME? | X63: =MAX(F63-50,0)*中国_中债国债到期收益率_1年!H63*100/365 -> 14.794521 | Y63: =SUM($X$3:X63) -> 913.95397 | AB63: =Z63*Return!F63*100 -> 0 | AD63: =SUM($AB$3:AB63)+SUM($AC$3:AC63) -> 0 | AE63: =Q63+W63+AD63-Y63 -> #NAME? | AF63: =AE63/$AI$1+1 -> #NAME? | AG63: =(AF63/AF62-1)-中国_中债国债到期收益率_1年!H63%/252 -> #NAME? | AH63: =MIN((AF63-MAX($AF$3:AF63))/MAX($AF$3:AF63),0) -> #NAME?
A64: 44802 | B64: 20 | C64: 30 | D64: 30 | F64: =SUM(B64:E64) -> 80 | G64: =B64 -> 20 | H64: =5*C64 -> 150 | I64: =9*D64 -> 270 | J64: =16*E64 -> 0 | K64: =SUM(G64:J64) -> 440 | L64: =G64*Return!B64*100 -> -2 | M64: =H64*Return!C64*100 -> 22.5 | N64: =I64*Return!D64*100 -> -108 | O64: =J64*Return!E64*100 -> 0 | P64: =SUM(L64:O64) -> -87.5 | Q64: =SUM($P$3:P64) -> #NAME? | R64: =B64*中国_中债国债到期收益率_1年!B63/365*100 -> 9.820274 | S64: =C64*中国_中债国债到期收益率_1年!C63/365*100 -> 20.081918 | T64: =D64*中国_中债国债到期收益率_1年!D63/365*100 -> 21.723288 | U64: =E64*中国_中债国债到期收益率_1年!E63/365*100 -> 0 | V64: =SUM(R64:U64) -> 51.625479 | W64: =SUM($V$3:V64) -> #NAME? | X64: =MAX(F64-50,0)*中国_中债国债到期收益率_1年!H64*100/365 -> 14.794521 | Y64: =SUM($X$3:X64) -> 928.74849 | AB64: =Z64*Return!F64*100 -> 0 | AD64: =SUM($AB$3:AB64)+SUM($AC$3:AC64) -> 0 | AE64: =Q64+W64+AD64-Y64 -> #NAME? | AF64: =AE64/$AI$1+1 -> #NAME? | AG64: =(AF64/AF63-1)-中国_中债国债到期收益率_1年!H64%/252 -> #NAME? | AH64: =MIN((AF64-MAX($AF$3:AF64))/MAX($AF$3:AF64),0) -> #NAME?
A65: 44803 | B65: 20 | C65: 30 | D65: 30 | F65: =SUM(B65:E65) -> 80 | G65: =B65 -> 20 | H65: =5*C65 -> 150 | I65: =9*D65 -> 270 | J65: =16*E65 -> 0 | K65: =SUM(G65:J65) -> 440 | L65: =G65*Return!B65*100 -> 72.2 | M65: =H65*Return!C65*100 -> 454.5 | N65: =I65*Return!D65*100 -> 553.5 | O65: =J65*Return!E65*100 -> 0 | P65: =SUM(L65:O65) -> 1080.2 | Q65: =SUM($P$3:P65) -> #NAME? | R65: =B65*中国_中债国债到期收益率_1年!B64/365*100 -> 9.6224658 | S65: =C65*中国_中债国债到期收益率_1年!C64/365*100 -> 19.832877 | T65: =D65*中国_中债国债到期收益率_1年!D64/365*100 -> 21.554795 | U65: =E65*中国_中债国债到期收益率_1年!E64/365*100 -> 0 | V65: =SUM(R65:U65) -> 51.010137 | W65: =SUM($V$3:V65) -> #NAME? | X65: =MAX(F65-50,0)*中国_中债国债到期收益率_1年!H65*100/365 -> 14.383562 | Y65: =SUM($X$3:X65) -> 943.13205 | AB65: =Z65*Return!F65*100 -> 0 | AD65: =SUM($AB$3:AB65)+SUM($AC$3:AC65) -> 0 | AE65: =Q65+W65+AD65-Y65 -> #NAME? | AF65: =AE65/$AI$1+1 -> #NAME? | AG65: =(AF65/AF64-1)-中国_中债国债到期收益率_1年!H65%/252 -> #NAME? | AH65: =MIN((AF65-MAX($AF$3:AF65))/MAX($AF$3:AF65),0) -> #NAME?
A66: 44804 | B66: 20 | C66: 30 | D66: 30 | F66: =SUM(B66:E66) -> 80 | G66: =B66 -> 20 | H66: =5*C66 -> 150 | I66: =9*D66 -> 270 | J66: =16*E66 -> 0 | K66: =SUM(G66:J66) -> 440 | L66: =G66*Return!B66*100 -> 31 | M66: =H66*Return!C66*100 -> 88.5 | N66: =I66*Return!D66*100 -> 256.5 | O66: =J66*Return!E66*100 -> 0 | P66: =SUM(L66:O66) -> 376 | Q66: =SUM($P$3:P66) -> #NAME? | R66: =B66*中国_中债国债到期收益率_1年!B65/365*100 -> 9.5375342 | S66: =C66*中国_中债国债到期收益率_1年!C65/365*100 -> 19.784384 | T66: =D66*中国_中债国债到期收益率_1年!D65/365*100 -> 21.476712 | U66: =E66*中国_中债国债到期收益率_1年!E65/365*100 -> 0 | V66: =SUM(R66:U66) -> 50.79863 | W66: =SUM($V$3:V66) -> #NAME? | X66: =MAX(F66-50,0)*中国_中债国债到期收益率_1年!H66*100/365 -> 13.972603 | Y66: =SUM($X$3:X66) -> 957.10466 | AB66: =Z66*Return!F66*100 -> 0 | AD66: =SUM($AB$3:AB66)+SUM($AC$3:AC66) -> 0 | AE66: =Q66+W66+AD66-Y66 -> #NAME? | AF66: =AE66/$AI$1+1 -> #NAME? | AG66: =(AF66/AF65-1)-中国_中债国债到期收益率_1年!H66%/252 -> #NAME? | AH66: =MIN((AF66-MAX($AF$3:AF66))/MAX($AF$3:AF66),0) -> #NAME?
A67: 44805 | B67: 20 | C67: 30 | D67: 30 | F67: =SUM(B67:E67) -> 80 | G67: =B67 -> 20 | H67: =5*C67 -> 150 | I67: =9*D67 -> 270 | J67: =16*E67 -> 0 | K67: =SUM(G67:J67) -> 440 | L67: =G67*Return!B67*100 -> 5.6 | M67: =H67*Return!C67*100 -> 9 | N67: =I67*Return!D67*100 -> -256.5 | O67: =J67*Return!E67*100 -> 0 | P67: =SUM(L67:O67) -> -241.9 | Q67: =SUM($P$3:P67) -> #NAME? | R67: =B67*中国_中债国债到期收益率_1年!B66/365*100 -> 9.5221918 | S67: =C67*中国_中债国债到期收益率_1年!C66/365*100 -> 19.779452 | T67: =D67*中国_中债国债到期收益率_1年!D66/365*100 -> 21.554795 | U67: =E67*中国_中债国债到期收益率_1年!E66/365*100 -> 0 | V67: =SUM(R67:U67) -> 50.856438 | W67: =SUM($V$3:V67) -> #NAME? | X67: =MAX(F67-50,0)*中国_中债国债到期收益率_1年!H67*100/365 -> 12.328767 | Y67: =SUM($X$3:X67) -> 969.43342 | AB67: =Z67*Return!F67*100 -> 0 | AD67: =SUM($AB$3:AB67)+SUM($AC$3:AC67) -> 0 | AE67: =Q67+W67+AD67-Y67 -> #NAME? | AF67: =AE67/$AI$1+1 -> #NAME? | AG67: =(AF67/AF66-1)-中国_中债国债到期收益率_1年!H67%/252 -> #NAME? | AH67: =MIN((AF67-MAX($AF$3:AF67))/MAX($AF$3:AF67),0) -> #NAME?
A68: 44806 | B68: 20 | C68: 30 | D68: 30 | F68: =SUM(B68:E68) -> 80 | G68: =B68 -> 20 | H68: =5*C68 -> 150 | I68: =9*D68 -> 270 | J68: =16*E68 -> 0 | K68: =SUM(G68:J68) -> 440 | L68: =G68*Return!B68*100 -> 27 | M68: =H68*Return!C68*100 -> 150 | N68: =I68*Return!D68*100 -> 270 | O68: =J68*Return!E68*100 -> 0 | P68: =SUM(L68:O68) -> 447 | Q68: =SUM($P$3:P68) -> #NAME? | R68: =B68*中国_中债国债到期收益率_1年!B67/365*100 -> 9.4482192 | S68: =C68*中国_中债国债到期收益率_1年!C67/365*100 -> 19.69726 | T68: =D68*中国_中债国债到期收益率_1年!D67/365*100 -> 21.472603 | U68: =E68*中国_中债国债到期收益率_1年!E67/365*100 -> 0 | V68: =SUM(R68:U68) -> 50.618082 | W68: =SUM($V$3:V68) -> #NAME? | X68: =MAX(F68-50,0)*中国_中债国债到期收益率_1年!H68*100/365 -> 12.492329 | Y68: =SUM($X$3:X68) -> 981.92575 | AB68: =Z68*Return!F68*100 -> 0 | AD68: =SUM($AB$3:AB68)+SUM($AC$3:AC68) -> 0 | AE68: =Q68+W68+AD68-Y68 -> #NAME? | AF68: =AE68/$AI$1+1 -> #NAME? | AG68: =(AF68/AF67-1)-中国_中债国债到期收益率_1年!H68%/252 -> #NAME? | AH68: =MIN((AF68-MAX($AF$3:AF68))/MAX($AF$3:AF68),0) -> #NAME?
A69: 44809 | B69: 20 | C69: 30 | D69: 30 | F69: =SUM(B69:E69) -> 80 | G69: =B69 -> 20 | H69: =5*C69 -> 150 | I69: =9*D69 -> 270 | J69: =16*E69 -> 0 | K69: =SUM(G69:J69) -> 440 | L69: =G69*Return!B69*100 -> 10 | M69: =H69*Return!C69*100 -> -88.5 | N69: =I69*Return!D69*100 -> -272.7 | O69: =J69*Return!E69*100 -> 0 | P69: =SUM(L69:O69) -> -351.2 | Q69: =SUM($P$3:P69) -> #NAME? | R69: =B69*中国_中债国债到期收益率_1年!B68/365*100 -> 9.4208219 | S69: =C69*中国_中债国债到期收益率_1年!C68/365*100 -> 19.745753 | T69: =D69*中国_中债国债到期收益率_1年!D68/365*100 -> 21.555616 | U69: =E69*中国_中债国债到期收益率_1年!E68/365*100 -> 0 | V69: =SUM(R69:U69) -> 50.722192 | W69: =SUM($V$3:V69) -> #NAME? | X69: =MAX(F69-50,0)*中国_中债国债到期收益率_1年!H69*100/365 -> 12.328767 | Y69: =SUM($X$3:X69) -> 994.25452 | AB69: =Z69*Return!F69*100 -> 0 | AD69: =SUM($AB$3:AB69)+SUM($AC$3:AC69) -> 0 | AE69: =Q69+W69+AD69-Y69 -> #NAME? | AF69: =AE69/$AI$1+1 -> #NAME? | AG69: =(AF69/AF68-1)-中国_中债国债到期收益率_1年!H69%/252 -> #NAME? | AH69: =MIN((AF69-MAX($AF$3:AF69))/MAX($AF$3:AF69),0) -> #NAME?
...

Sheet Charts
A37: =DATE(2024,1,1) -> 45292
A38: size | B38: 50
A39: total | B39: =PnL!AE620 -> 37812.968
A40: return | B40: =B39/B38/10000*365/(PnL!A622-A37) -> 0.085195884
A41: dev | B41: =STDEV.P(PnL!AG401:PnL!AG622)*SQRT(252) -> 0.022677039 | C41: 1.8
A42: rfr | B42: =AVERAGE(中国_中债国债到期收益率_1年!H401:中国_中债国债到期收益率_1年!H622)/100 -> 0.019693937
A43: sr | B43: =(B40-B42)/B41 -> 2.88847 | C43: 3.55
A44: MDD | B44: =MIN(PnL!AH401:PnL!AH622) -> -0.0076145661 | C44: 0.82
