Workbook

Sheet 中国_中债国债到期收益率_1年
A1: 日期 | B1: 中债国债到期收益率:1年 | C1: 中债国债到期收益率:5年 | D1: 中国:中债国债到期收益率:10年 | E1: 中债国债到期收益率:30年 | F1: 利率互换:FR007:1年 | G1: 利率互换:FR007:5年 | H1: FR007 | J1: 日期 | K1: Wind基金指数:短期纯债型基金 | L1: Wind基金指数:长期纯债型基金 | M1: Wind基金指数:债券型基金 | N1: 中证基金指数:债券基金 | O1: Wind基金指数:短期纯债型基金 | P1: Wind基金指数:长期纯债型基金 | Q1: Wind基金指数:债券型基金 | R1: 中证基金指数:债券基金 | S1: Short-Term Bond Fund Index | T1: Long-Term Bond Fund Index | U1: Compound Bond Fund Index | V1: Short-Term Bond Fund Index
A2: 44713 | B2: =[1]!WSD("S0059744,S0059747,S0059749,S0059752,M0048486,M0048490,M0017153","EDBclose","2022-06-01","","TradingCalendar=SSE","PriceAdj=F","rptType=1","ShowCodes=N","ShowParams=Y","cols=7;rows=663") -> Fetching... | C2: 2.5594 | D2: 2.7551 | E2: 3.2643 | F2: 2.0815 | G2: 2.5254 | H2: 1.64 | J2: 44713 | K2: =[1]!WSD("C8439326,M0062649,M0062646,M0062637","EDBclose","2022-06-01","","TradingCalendar=SSE","PriceAdj=F","rptType=1","ShowParams=Y","cols=4;rows=642") -> Fetching... | L2: 2292.1735 | M2: 2822.8553 | N2: 2994.1983
A3: 44714 | B3: 1.9564 | C3: 2.563 | D3: 2.7601 | E3: 3.2669 | F3: 2.0917 | G3: 2.5397 | H3: 1.65 | J3: 44714 | K3: 1710.1206 | L3: 2291.3609 | M3: 2822.9784 | N3: 2993.9984 | O3: =K3/$K$2-1 -> #VALUE! | P3: =L3/$L$2-1 -> -0.00035451069 | Q3: =M3/$M$2-1 -> 4.3608328e-05 | R3: =N3/$N$2-1 -> -6.6762445e-05 | S3: =(O3+1) -> #VALUE! | T3: =(P3+1) -> 0.99964549 | U3: =(Q3+1) -> 1.0000436 | V3: =(R3+1) -> 0.99993324
A4: 44718 | B4: 2.0199 | C4: 2.5994 | D4: 2.7776 | E4: 3.2745 | F4: 2.1125 | G4: 2.5583 | H4: 1.68 | J4: 44718 | K4: 1709.9695 | L4: 2290.4125 | M4: 2824.8586 | N4: 2995.3693 | O4: =K4/$K$2-1 -> #VALUE! | P4: =L4/$L$2-1 -> -0.00076826645 | Q4: =M4/$M$2-1 -> 0.00070967152 | R4: =N4/$N$2-1 -> 0.00039108966 | S4: =(O4+1) -> #VALUE! | T4: =(P4+1) -> 0.99923173 | U4: =(Q4+1) -> 1.0007097 | V4: =(R4+1) -> 1.0003911
A5: 44719 | B5: 2.018 | C5: 2.5842 | D5: 2.7576 | E5: 3.2671 | F5: 2.12 | G5: 2.5627 | H5: 1.65 | J5: 44719 | K5: 1709.6981 | L5: 2290.235 | M5: 2824.5791 | N5: 2995.1037 | O5: =K5/$K$2-1 -> #VALUE! | P5: =L5/$L$2-1 -> -0.00084570387 | Q5: =M5/$M$2-1 -> 0.00061065829 | R5: =N5/$N$2-1 -> 0.00030238478 | S5: =(O5+1) -> #VALUE! | T5: =(P5+1) -> 0.9991543 | U5: =(Q5+1) -> 1.0006107 | V5: =(R5+1) -> 1.0003024
A6: 44720 | B6: 2.0282 | C6: 2.585 | D6: 2.7661 | E6: 3.2746 | F6: 2.1052 | G6: 2.55 | H6: 1.65 | J6: 44720 | K6: 1709.7836 | L6: 2290.3662 | M6: 2825.413 | N6: 2996.0029 | O6: =K6/$K$2-1 -> #VALUE! | P6: =L6/$L$2-1 -> -0.00078846562 | Q6: =M6/$M$2-1 -> 0.00090606841 | R6: =N6/$N$2-1 -> 0.00060269889 | S6: =(O6+1) -> #VALUE! | T6: =(P6+1) -> 0.99921153 | U6: =(Q6+1) -> 1.0009061 | V6: =(R6+1) -> 1.0006027
A7: 44721 | B7: 2.0151 | C7: 2.5726 | D7: 2.7576 | E7: 3.2646 | F7: 2.0984 | G7: 2.5421 | H7: 1.65 | J7: 44721 | K7: 1709.9507 | L7: 2290.9022 | M7: 2824.6044 | N7: 2995.4486 | O7: =K7/$K$2-1 -> #VALUE! | P7: =L7/$L$2-1 -> -0.00055462643 | Q7: =M7/$M$2-1 -> 0.00061962085 | R7: =N7/$N$2-1 -> 0.00041757421 | S7: =(O7+1) -> #VALUE! | T7: =(P7+1) -> 0.99944537 | U7: =(Q7+1) -> 1.0006196 | V7: =(R7+1) -> 1.0004176
A8: 44722 | B8: 2.0051 | C8: 2.568 | D8: 2.7526 | E8: 3.2622 | F8: 2.0934 | G8: 2.5368 | H8: 1.62 | J8: 44722 | K8: 1710.1838 | L8: 2291.4577 | M8: 2827.9087 | N8: 2998.1991 | O8: =K8/$K$2-1 -> #VALUE! | P8: =L8/$L$2-1 -> -0.00031228003 | Q8: =M8/$M$2-1 -> 0.0017901732 | R8: =N8/$N$2-1 -> 0.001336184 | S8: =(O8+1) -> #VALUE! | T8: =(P8+1) -> 0.99968772 | U8: =(Q8+1) -> 1.0017902 | V8: =(R8+1) -> 1.0013362
A9: 44725 | B9: 2.0026 | C9: 2.5899 | D9: 2.7652 | E9: 3.2698 | F9: 2.1035 | G9: 2.5507 | H9: 1.65 | J9: 44725 | K9: 1710.4629 | L9: 2291.6915 | M9: 2827.4758 | N9: 2997.6274 | O9: =K9/$K$2-1 -> #VALUE! | P9: =L9/$L$2-1 -> -0.00021028077 | Q9: =M9/$M$2-1 -> 0.0016368179 | R9: =N9/$N$2-1 -> 0.0011452481 | S9: =(O9+1) -> #VALUE! | T9: =(P9+1) -> 0.99978972 | U9: =(Q9+1) -> 1.0016368 | V9: =(R9+1) -> 1.0011452
A10: 44726 | B10: 2.0176 | C10: 2.5952 | D10: 2.7702 | E10: 3.2698 | F10: 2.1193 | G10: 2.5675 | H10: 1.63 | J10: 44726 | K10: 1710.5377 | L10: 2291.7149 | M10: 2827.687 | N10: 2998.1169 | O10: =K10/$K$2-1 -> #VALUE! | P10: =L10/$L$2-1 -> -0.00020007211 | Q10: =M10/$M$2-1 -> 0.0017116357 | R10: =N10/$N$2-1 -> 0.001308731 | S10: =(O10+1) -> #VALUE! | T10: =(P10+1) -> 0.99979993 | U10: =(Q10+1) -> 1.0017116 | V10: =(R10+1) -> 1.0013087
A11: 44727 | B11: 2.036 | C11: 2.6112 | D11: 2.7827 | E11: 3.2722 | F11: 2.127 | G11: 2.5755 | H11: 1.63 | J11: 44727 | K11: 1710.6381 | L11: 2291.7655 | M11: 2828.9152 | N11: 2999.2226 | O11: =K11/$K$2-1 -> #VALUE! | P11: =L11/$L$2-1 -> -0.000177997 | Q11: =M11/$M$2-1 -> 0.0021467271 | R11: =N11/$N$2-1 -> 0.0016780118 | S11: =(O11+1) -> #VALUE! | T11: =(P11+1) -> 0.999822 | U11: =(Q11+1) -> 1.0021467 | V11: =(R11+1) -> 1.001678
A12: 44728 | B12: 2.0352 | C12: 2.5936 | D12: 2.7728 | E12: 3.2623 | F12: 2.1182 | G12: 2.5698 | H12: 1.65 | J12: 44728 | K12: 1710.8593 | L12: 2292.2632 | M12: 2831.3479 | N12: 2999.5546 | O12: =K12/$K$2-1 -> #VALUE! | P12: =L12/$L$2-1 -> 3.9133163e-05 | Q12: =M12/$M$2-1 -> 0.0030085141 | R12: =N12/$N$2-1 -> 0.0017888929 | S12: =(O12+1) -> #VALUE! | T12: =(P12+1) -> 1.0000391 | U12: =(Q12+1) -> 1.0030085 | V12: =(R12+1) -> 1.0017889
A13: 44729 | B13: 2.0102 | C13: 2.5944 | D13: 2.7752 | E13: 3.2598 | F13: 2.1058 | G13: 2.5594 | H13: 1.7 | J13: 44729 | K13: 1711.2067 | L13: 2293.2532 | M13: 2834.2881 | N13: 3002.0181 | O13: =K13/$K$2-1 -> #VALUE! | P13: =L13/$L$2-1 -> 0.00047103764 | Q13: =M13/$M$2-1 -> 0.0040500836 | R13: =N13/$N$2-1 -> 0.0026116507 | S13: =(O13+1) -> #VALUE! | T13: =(P13+1) -> 1.000471 | U13: =(Q13+1) -> 1.0040501 | V13: =(R13+1) -> 1.0026117
A14: 44732 | B14: 2.0056 | C14: 2.6163 | D14: 2.7853 | E14: 3.2674 | F14: 2.1311 | G14: 2.5829 | H14: 1.7 | J14: 44732 | K14: 1711.4367 | L14: 2293.295 | M14: 2834.7104 | N14: 3002.3644 | O14: =K14/$K$2-1 -> #VALUE! | P14: =L14/$L$2-1 -> 0.00048927361 | Q14: =M14/$M$2-1 -> 0.0041996839 | R14: =N14/$N$2-1 -> 0.0027273077 | S14: =(O14+1) -> #VALUE! | T14: =(P14+1) -> 1.0004893 | U14: =(Q14+1) -> 1.0041997 | V14: =(R14+1) -> 1.0027273
... A144: 44918 | B144: 2.2269 | C144: 2.6062 | D144: 2.8251 | E144: 3.2152 | F144: 2.1688 | G144: 2.7376 | H144: 1.8 | J144: 44922 | K144: 1722.841 | L144: 2308.5118 | M144: 2834.6268 | N144: 3007.852 | O144: =K144/$K$2-1 -> #VALUE! | P144: =L144/$L$2-1 -> 0.0071278636 | Q144: =M144/$M$2-1 -> 0.0041700685 | R144: =N144/$N$2-1 -> 0.004560052 | S144: =(O144+1) -> #VALUE! | T144: =(P144+1) -> 1.0071279 | U144: =(Q144+1) -> 1.0041701 | V144: =(R144+1) -> 1.0045601
A145: 44921 | B145: 2.2469 | C145: 2.6276 | D145: 2.8378 | E145: 3.2202 | H145: 2.0558 | J145: 44923 | K145: 1723.1405 | L145: 2309.0169 | M145: 2834.2824 | N145: 3007.7438 | O145: =K145/$K$2-1 -> #VALUE! | P145: =L145/$L$2-1 -> 0.0073482221 | Q145: =M145/$M$2-1 -> 0.0040480644 | R145: =N145/$N$2-1 -> 0.0045239155 | S145: =(O145+1) -> #VALUE! | T145: =(P145+1) -> 1.0073482 | U145: =(Q145+1) -> 1.0040481 | V145: =(R145+1) -> 1.0045239
A146: 44922 | B146: 2.2469 | C146: 2.6703 | D146: 2.8657 | E146: 3.2175 | F146: 2.2315 | G146: 2.7833 | H146: 5 | J146: 44924 | K146: 1723.7989 | L146: 2310.3846 | M146: 2835.0573 | N146: 3008.5997 | O146: =K146/$K$2-1 -> #VALUE! | P146: =L146/$L$2-1 -> 0.0079449047 | Q146: =M146/$M$2-1 -> 0.0043225737 | R146: =N146/$N$2-1 -> 0.0048097683 | S146: =(O146+1) -> #VALUE! | T146: =(P146+1) -> 1.0079449 | U146: =(Q146+1) -> 1.0043226 | V146: =(R146+1) -> 1.0048098
A147: 44923 | B147: 2.2369 | C147: 2.6704 | D147: 2.8503 | E147: 3.2127 | F147: 2.2309 | G147: 2.7813 | H147: 4.8 | J147: 44925 | K147: 1724.4299 | L147: 2311.8141 | M147: 2836.8269 | N147: 3010.5565 | O147: =K147/$K$2-1 -> #VALUE! | P147: =L147/$L$2-1 -> 0.0085685486 | Q147: =M147/$M$2-1 -> 0.0049494567 | R147: =N147/$N$2-1 -> 0.0054632988 | S147: =(O147+1) -> #VALUE! | T147: =(P147+1) -> 1.0085685 | U147: =(Q147+1) -> 1.0049495 | V147: =(R147+1) -> 1.0054633
A148: 44924 | B148: 2.1669 | C148: 2.6382 | D148: 2.8376 | E148: 3.1926 | F148: 2.2007 | G148: 2.7574 | H148: 3.5 | J148: 44929 | K148: 1725.4384 | L148: 2313.2716 | M148: 2840.3219 | N148: 3013.691 | S148: =(O148+1) -> 1 | T148: =(P148+1) -> 1 | U148: =(Q148+1) -> 1 | V148: =(R148+1) -> 1
A149: 44925 | B149: 2.0969 | C149: 2.6446 | D149: 2.8353 | E149: 3.1952 | F149: 2.1801 | G149: 2.759 | H149: 3 | J149: 44930 | K149: 1726.2178 | L149: 2314.6425 | M149: 2842.4883 | N149: 3016.0183 | O149: =K149/$K$148-1 -> 0.00045171129 | P149: =L149/$L$148-1 -> 0.00059262388 | Q149: =M149/$M$148-1 -> 0.00076273045 | R149: =N149/$N$148-1 -> 0.00077224241 | S149: =(O149+1) -> 1.0004517 | T149: =(P149+1) -> 1.0005926 | U149: =(Q149+1) -> 1.0007627 | V149: =(R149+1) -> 1.0007722
A150: 44926 | B150: 2.0969 | C150: 2.6446 | D150: 2.8353 | E150: 3.1952 | J150: 44931 | K150: 1726.6447 | L150: 2315.0324 | M150: 2845.7135 | N150: 3018.7155 | O150: =K150/$K$148-1 -> 0.00069912667 | P150: =L150/$L$148-1 -> 0.00076117305 | Q150: =M150/$M$148-1 -> 0.0018982355 | R150: =N150/$N$148-1 -> 0.0016672247 | S150: =(O150+1) -> 1.0006991 | T150: =(P150+1) -> 1.0007612 | U150: =(Q150+1) -> 1.0018982 | V150: =(R150+1) -> 1.0016672
A151: 44929 | B151: 2.112 | C151: 2.6298 | D151: 2.8228 | E151: 3.193 | F151: 2.1752 | G151: 2.7651 | H151: 1.9243 | J151: 44932 | K151: 1726.5932 | L151: 2314.7103 | M151: 2846.4189 | N151: 3018.751 | O151: =K151/$K$148-1 -> 0.00066927918 | P151: =L151/$L$148-1 -> 0.00062193302 | Q151: =M151/$M$148-1 -> 0.0021465877 | R151: =N151/$N$148-1 -> 0.0016790043 | S151: =(O151+1) -> 1.0006693 | T151: =(P151+1) -> 1.0006219 | U151: =(Q151+1) -> 1.0021466 | V151: =(R151+1) -> 1.001679
A152: 44930 | B152: 2.067 | C152: 2.6071 | D152: 2.8103 | E152: 3.1931 | F152: 2.1469 | G152: 2.7342 | H152: 1.7 | J152: 44935 | K152: 1726.9309 | L152: 2314.6985 | M152: 2847.2474 | N152: 3019.522 | O152: =K152/$K$148-1 -> 0.00086499756 | P152: =L152/$L$148-1 -> 0.00061683202 | Q152: =M152/$M$148-1 -> 0.00243828 | R152: =N152/$N$148-1 -> 0.0019348367 | S152: =(O152+1) -> 1.000865 | T152: =(P152+1) -> 1.0006168 | U152: =(Q152+1) -> 1.0024383 | V152: =(R152+1) -> 1.0019348
A153: 44931 | B153: 2.082 | C153: 2.625 | D153: 2.8304 | E153: 3.2056 | F153: 2.144 | G153: 2.7366 | H153: 1.7 | J153: 44936 | K153: 1726.5686 | L153: 2313.2849 | M153: 2845.4037 | N153: 3017.4835 | O153: =K153/$K$148-1 -> 0.00065502194 | P153: =L153/$L$148-1 -> 5.749433e-06 | Q153: =M153/$M$148-1 -> 0.0017891634 | R153: =N153/$N$148-1 -> 0.0012584236 | S153: =(O153+1) -> 1.000655 | T153: =(P153+1) -> 1.0000057 | U153: =(Q153+1) -> 1.0017892 | V153: =(R153+1) -> 1.0012584
A154: 44932 | B154: 2.097 | C154: 2.6495 | D154: 2.8328 | E154: 3.2106 | F154: 2.1611 | G154: 2.7604 | H154: 1.75 | J154: 44937 | K154: 1726.5282 | L154: 2313.3121 | M154: 2844.8369 | N154: 3017.1255 | O154: =K154/$K$148-1 -> 0.0006316076 | P154: =L154/$L$148-1 -> 1.7507672e-05 | Q154: =M154/$M$148-1 -> 0.0015896086 | R154: =N154/$N$148-1 -> 0.0011396324 | S154: =(O154+1) -> 1.0006316 | T154: =(P154+1) -> 1.0000175 | U154: =(Q154+1) -> 1.0015896 | V154: =(R154+1) -> 1.0011396
A155: 44935 | B155: 2.0996 | C155: 2.6649 | D155: 2.8428 | E155: 3.2156 | F155: 2.1796 | G155: 2.7701 | H155: 1.85 | J155: 44938 | K155: 1726.8308 | L155: 2313.6384 | M155: 2845.4832 | N155: 3017.6158 | O155: =K155/$K$148-1 -> 0.00080698332 | P155: =L155/$L$148-1 -> 0.00015856331 | Q155: =M155/$M$148-1 -> 0.0018171532 | R155: =N155/$N$148-1 -> 0.0013023233 | S155: =(O155+1) -> 1.000807 | T155: =(P155+1) -> 1.0001586 | U155: =(Q155+1) -> 1.0018172 | V155: =(R155+1) -> 1.0013023
A156: 44936 | B156: 2.122 | C156: 2.7104 | D156: 2.8602 | E156: 3.2331 | F156: 2.2331 | G156: 2.8136 | H156: 1.98 | J156: 44939 | K156: 1726.9672 | L156: 2313.4236 | M156: 2846.2115 | N156: 3018.338 | O156: =K156/$K$148-1 -> 0.00088603569 | P156: =L156/$L$148-1 -> 6.5707805e-05 | Q156: =M156/$M$148-1 -> 0.0020735678 | R156: =N156/$N$148-1 -> 0.001541963 | S156: =(O156+1) -> 1.000886 | T156: =(P156+1) -> 1.0000657 | U156: =(Q156+1) -> 1.0020736 | V156: =(R156+1) -> 1.001542
A157: 44937 | B157: 2.127 | C157: 2.6989 | D157: 2.8603 | E157: 3.2331 | F157: 2.2547 | G157: 2.8284 | H157: 2.3 | J157: 44942 | K157: 1726.9743 | L157: 2312.5787 | M157: 2847.5417 | N157: 3018.9765 | O157: =K157/$K$148-1 -> 0.00089015058 | P157: =L157/$L$148-1 -> -0.00029953249 | Q157: =M157/$M$148-1 -> 0.002541895 | R157: =N157/$N$148-1 -> 0.0017538294 | S157: =(O157+1) -> 1.0008902 | T157: =(P157+1) -> 0.99970047 | U157: =(Q157+1) -> 1.0025419 | V157: =(R157+1) -> 1.0017538
A158: 44938 | B158: 2.097 | C158: 2.6974 | D158: 2.8778 | E158: 3.2378 | F158: 2.2357 | G158: 2.8169 | H158: 2.2 | J158: 44943 | K158: 1727.078 | L158: 2312.79 | M158: 2848.5809 | N158: 3019.5953 | O158: =K158/$K$148-1 -> 0.00095025125 | P158: =L158/$L$148-1 -> -0.00020818999 | Q158: =M158/$M$148-1 -> 0.002907769 | R158: =N158/$N$148-1 -> 0.0019591591 | S158: =(O158+1) -> 1.0009503 | T158: =(P158+1) -> 0.99979181 | U158: =(Q158+1) -> 1.0029078 | V158: =(R158+1) -> 1.0019592
A159: 44939 | B159: 2.097 | C159: 2.7096 | D159: 2.901 | E159: 3.2476 | F159: 2.2449 | G159: 2.8414 | H159: 1.95 | J159: 44944 | K159: 1727.3637 | L159: 2312.9364 | M159: 2849.3144 | N159: 3020.1327 | O159: =K159/$K$148-1 -> 0.0011158324 | P159: =L159/$L$148-1 -> -0.000144903 | Q159: =M159/$M$148-1 -> 0.0031660144 | R159: =N159/$N$148-1 -> 0.0021374786 | S159: =(O159+1) -> 1.0011158 | T159: =(P159+1) -> 0.9998551 | U159: =(Q159+1) -> 1.003166 | V159: =(R159+1) -> 1.0021375
A160: 44942 | B160: 2.127 | C160: 2.7571 | D160: 2.9167 | E160: 3.2677 | F160: 2.2877 | G160: 2.8972 | H160: 2.15 | J160: 44945 | K160: 1727.5927 | L160: 2313.2007 | M160: 2850.7141 | N160: 3021.7984 | O160: =K160/$K$148-1 -> 0.0012485523 | P160: =L160/$L$148-1 -> -3.0649233e-05 | Q160: =M160/$M$148-1 -> 0.0036588106 | R160: =N160/$N$148-1 -> 0.0026901895 | S160: =(O160+1) -> 1.0012486 | T160: =(P160+1) -> 0.99996935 | U160: =(Q160+1) -> 1.0036588 | V160: =(R160+1) -> 1.0026902
A161: 44943 | B161: 2.127 | C161: 2.7346 | D161: 2.9017 | E161: 3.2531 | F161: 2.297 | G161: 2.8954 | H161: 2.6 | J161: 44946 | K161: 1727.9404 | L161: 2313.6147 | M161: 2852.8183 | N161: 3023.4842 | O161: =K161/$K$148-1 -> 0.0014500663 | P161: =L161/$L$148-1 -> 0.00014831808 | Q161: =M161/$M$148-1 -> 0.0043996422 | R161: =N161/$N$148-1 -> 0.00324957 | S161: =(O161+1) -> 1.0014501 | T161: =(P161+1) -> 1.0001483 | U161: =(Q161+1) -> 1.0043996 | V161: =(R161+1) -> 1.0032496
A162: 44944 | B162: 2.1615 | C162: 2.7257 | D162: 2.9222 | E162: 3.2754 | F162: 2.2933 | G162: 2.8874 | H162: 2.6 | J162: 44956 | K162: 1729.3595 | L162: 2315.1651 | M162: 2855.2599 | N162: 3025.7128 | O162: =K162/$K$148-1 -> 0.0022725239 | P162: =L162/$L$148-1 -> 0.00081853769 | Q162: =M162/$M$148-1 -> 0.005259263 | R162: =N162/$N$148-1 -> 0.0039890619 | S162: =(O162+1) -> 1.0022725 | T162: =(P162+1) -> 1.0008185 | U162: =(Q162+1) -> 1.0052593 | V162: =(R162+1) -> 1.0039891
... A164: 44946 | B164: 2.1648 | C164: 2.7288 | D164: 2.9331 | E164: 3.2779 | F164: 2.2937 | G164: 2.9066 | H164: 2 | J164: 44958 | K164: 1729.7074 | L164: 2315.6508 | M164: 2856.6913 | N164: 3026.8328 | O164: =K164/$K$148-1 -> 0.0024741538 | P164: =L164/$L$148-1 -> 0.0010285001 | Q164: =M164/$M$148-1 -> 0.00576322 | R164: =N164/$N$148-1 -> 0.0043606992 | S164: =(O164+1) -> 1.0024742 | T164: =(P164+1) -> 1.0010285 | U164: =(Q164+1) -> 1.0057632 | V164: =(R164+1) -> 1.0043607
A165: 44954 | B165: 2.1496 | C165: 2.7283 | D165: 2.9341 | E165: 3.283 | G165: 2.9434 | H165: 1.95 | J165: 44959 | K165: 1730.0096 | L165: 2316.3515 | M165: 2857.7854 | N165: 3027.9637 | O165: =K165/$K$148-1 -> 0.0026492977 | P165: =L165/$L$148-1 -> 0.0013314044 | Q165: =M165/$M$148-1 -> 0.0061484228 | R165: =N165/$N$148-1 -> 0.0047359534 | S165: =(O165+1) -> 1.0026493 | T165: =(P165+1) -> 1.0013314 | U165: =(Q165+1) -> 1.0061484 | V165: =(R165+1) -> 1.004736
A166: 44955 | B166: 2.1519 | C166: 2.7225 | D166: 2.9219 | E166: 3.2805 | H166: 1.854 | J166: 44960 | K166: 1730.4285 | L166: 2317.7603 | M166: 2858.0001 | N166: 3029.016 | O166: =K166/$K$148-1 -> 0.0028920766 | P166: =L166/$L$148-1 -> 0.001940412 | Q166: =M166/$M$148-1 -> 0.0062240128 | R166: =N166/$N$148-1 -> 0.0050851265 | S166: =(O166+1) -> 1.0028921 | T166: =(P166+1) -> 1.0019404 | U166: =(Q166+1) -> 1.006224 | V166: =(R166+1) -> 1.0050851
A167: 44956 | B167: 2.176 | C167: 2.7238 | D167: 2.9133 | E167: 3.2782 | F167: 2.3007 | G167: 2.9292 | H167: 2.14 | J167: 44963 | K167: 1730.8446 | L167: 2318.1894 | M167: 2856.0628 | N167: 3027.9664 | O167: =K167/$K$148-1 -> 0.0031332327 | P167: =L167/$L$148-1 -> 0.0021259069 | Q167: =M167/$M$148-1 -> 0.0055419423 | R167: =N167/$N$148-1 -> 0.0047368493 | S167: =(O167+1) -> 1.0031332 | T167: =(P167+1) -> 1.0021259 | U167: =(Q167+1) -> 1.0055419 | V167: =(R167+1) -> 1.0047368
A168: 44957 | B168: 2.1535 | C168: 2.7039 | D168: 2.8977 | E168: 3.2793 | F168: 2.2868 | G168: 2.9067 | H168: 2.2 | J168: 44964 | K168: 1730.975 | L168: 2318.3311 | M168: 2856.834 | N168: 3028.6115 | O168: =K168/$K$148-1 -> 0.0032088077 | P168: =L168/$L$148-1 -> 0.0021871621 | Q168: =M168/$M$148-1 -> 0.0058134608 | R168: =N168/$N$148-1 -> 0.0049509057 | S168: =(O168+1) -> 1.0032088 | T168: =(P168+1) -> 1.0021872 | U168: =(Q168+1) -> 1.0058135 | V168: =(R168+1) -> 1.0049509
A169: 44958 | B169: 2.1631 | C169: 2.7091 | D169: 2.9101 | E169: 3.2889 | F169: 2.2814 | G169: 2.9032 | H169: 2.05 | J169: 44965 | K169: 1731.1774 | L169: 2318.6648 | M169: 2856.3797 | N169: 3028.513 | O169: =K169/$K$148-1 -> 0.0033261112 | P169: =L169/$L$148-1 -> 0.0023314167 | Q169: =M169/$M$148-1 -> 0.0056535141 | R169: =N169/$N$148-1 -> 0.0049182215 | S169: =(O169+1) -> 1.0033261 | T169: =(P169+1) -> 1.0023314 | U169: =(Q169+1) -> 1.0056535 | V169: =(R169+1) -> 1.0049182
A170: 44959 | B170: 2.1507 | C170: 2.6945 | D170: 2.897 | E170: 3.2853 | F170: 2.266 | G170: 2.8845 | H170: 2.05 | J170: 44966 | K170: 1731.4448 | L170: 2319.2443 | M170: 2859.4268 | N170: 3031.0566 | O170: =K170/$K$148-1 -> 0.0034810863 | P170: =L170/$L$148-1 -> 0.0025819277 | Q170: =M170/$M$148-1 -> 0.0067263151 | R170: =N170/$N$148-1 -> 0.0057622364 | S170: =(O170+1) -> 1.0034811 | T170: =(P170+1) -> 1.0025819 | U170: =(Q170+1) -> 1.0067263 | V170: =(R170+1) -> 1.0057622
...

Sheet Return
A1: 日期
A2: 44713
A3: 44714
A4: 44718 | B4: =-中国_中债国债到期收益率_1年!B3+中国_中债国债到期收益率_1年!B2 -> #VALUE! | C4: =-中国_中债国债到期收益率_1年!C3+中国_中债国债到期收益率_1年!C2 -> -0.0036 | D4: =-中国_中债国债到期收益率_1年!D3+中国_中债国债到期收益率_1年!D2 -> -0.005 | E4: =-中国_中债国债到期收益率_1年!E3+中国_中债国债到期收益率_1年!E2 -> -0.0026 | F4: =-中国_中债国债到期收益率_1年!F3+中国_中债国债到期收益率_1年!F2 -> -0.0102 | G4: =-中国_中债国债到期收益率_1年!G3+中国_中债国债到期收益率_1年!G2 -> -0.0143
A5: 44719 | B5: =-中国_中债国债到期收益率_1年!B4+中国_中债国债到期收益率_1年!B3 -> -0.0635 | C5: =-中国_中债国债到期收益率_1年!C4+中国_中债国债到期收益率_1年!C3 -> -0.0364 | D5: =-中国_中债国债到期收益率_1年!D4+中国_中债国债到期收益率_1年!D3 -> -0.0175 | E5: =-中国_中债国债到期收益率_1年!E4+中国_中债国债到期收益率_1年!E3 -> -0.0076 | F5: =-中国_中债国债到期收益率_1年!F4+中国_中债国债到期收益率_1年!F3 -> -0.0208 | G5: =-中国_中债国债到期收益率_1年!G4+中国_中债国债到期收益率_1年!G3 -> -0.0186
A6: 44720 | B6: =-中国_中债国债到期收益率_1年!B5+中国_中债国债到期收益率_1年!B4 -> 0.0019 | C6: =-中国_中债国债到期收益率_1年!C5+中国_中债国债到期收益率_1年!C4 -> 0.0152 | D6: =-中国_中债国债到期收益率_1年!D5+中国_中债国债到期收益率_1年!D4 -> 0.02 | E6: =-中国_中债国债到期收益率_1年!E5+中国_中债国债到期收益率_1年!E4 -> 0.0074 | F6: =-中国_中债国债到期收益率_1年!F5+中国_中债国债到期收益率_1年!F4 -> -0.0075 | G6: =-中国_中债国债到期收益率_1年!G5+中国_中债国债到期收益率_1年!G4 -> -0.0044
A7: 44721 | B7: =-中国_中债国债到期收益率_1年!B6+中国_中债国债到期收益率_1年!B5 -> -0.0102 | C7: =-中国_中债国债到期收益率_1年!C6+中国_中债国债到期收益率_1年!C5 -> -0.0008 | D7: =-中国_中债国债到期收益率_1年!D6+中国_中债国债到期收益率_1年!D5 -> -0.0085 | E7: =-中国_中债国债到期收益率_1年!E6+中国_中债国债到期收益率_1年!E5 -> -0.0075 | F7: =-中国_中债国债到期收益率_1年!F6+中国_中债国债到期收益率_1年!F5 -> 0.0148 | G7: =-中国_中债国债到期收益率_1年!G6+中国_中债国债到期收益率_1年!G5 -> 0.0127
A8: 44722 | B8: =-中国_中债国债到期收益率_1年!B7+中国_中债国债到期收益率_1年!B6 -> 0.0131 | C8: =-中国_中债国债到期收益率_1年!C7+中国_中债国债到期收益率_1年!C6 -> 0.0124 | D8: =-中国_中债国债到期收益率_1年!D7+中国_中债国债到期收益率_1年!D6 -> 0.0085 | E8: =-中国_中债国债到期收益率_1年!E7+中国_中债国债到期收益率_1年!E6 -> 0.01 | F8: =-中国_中债国债到期收益率_1年!F7+中国_中债国债到期收益率_1年!F6 -> 0.0068 | G8: =-中国_中债国债到期收益率_1年!G7+中国_中债国债到期收益率_1年!G6 -> 0.0079
A9: 44725 | B9: =-中国_中债国债到期收益率_1年!B8+中国_中债国债到期收益率_1年!B7 -> 0.01 | C9: =-中国_中债国债到期收益率_1年!C8+中国_中债国债到期收益率_1年!C7 -> 0.0046 | D9: =-中国_中债国债到期收益率_1年!D8+中国_中债国债到期收益率_1年!D7 -> 0.005 | E9: =-中国_中债国债到期收益率_1年!E8+中国_中债国债到期收益率_1年!E7 -> 0.0024 | F9: =-中国_中债国债到期收益率_1年!F8+中国_中债国债到期收益率_1年!F7 -> 0.005 | G9: =-中国_中债国债到期收益率_1年!G8+中国_中债国债到期收益率_1年!G7 -> 0.0053
A10: 44726 | B10: =-中国_中债国债到期收益率_1年!B9+中国_中债国债到期收益率_1年!B8 -> 0.0025 | C10: =-中国_中债国债到期收益率_1年!C9+中国_中债国债到期收益率_1年!C8 -> -0.0219 | D10: =-中国_中债国债到期收益率_1年!D9+中国_中债国债到期收益率_1年!D8 -> -0.0126 | E10: =-中国_中债国债到期收益率_1年!E9+中国_中债国债到期收益率_1年!E8 -> -0.0076 | F10: =-中国_中债国债到期收益率_1年!F9+中国_中债国债到期收益率_1年!F8 -> -0.0101 | G10: =-中国_中债国债到期收益率_1年!G9+中国_中债国债到期收益率_1年!G8 -> -0.0139
A11: 44727 | B11: =-中国_中债国债到期收益率_1年!B10+中国_中债国债到期收益率_1年!B9 -> -0.015 | C11: =-中国_中债国债到期收益率_1年!C10+中国_中债国债到期收益率_1年!C9 -> -0.0053 | D11: =-中国_中债国债到期收益率_1年!D10+中国_中债国债到期收益率_1年!D9 -> -0.005 | E11: =-中国_中债国债到期收益率_1年!E10+中国_中债国债到期收益率_1年!E9 -> 0 | F11: =-中国_中债国债到期收益率_1年!F10+中国_中债国债到期收益率_1年!F9 -> -0.0158 | G11: =-中国_中债国债到期收益率_1年!G10+中国_中债国债到期收益率_1年!G9 -> -0.0168
A12: 44728 | B12: =-中国_中债国债到期收益率_1年!B11+中国_中债国债到期收益率_1年!B10 -> -0.0184 | C12: =-中国_中债国债到期收益率_1年!C11+中国_中债国债到期收益率_1年!C10 -> -0.016 | D12: =-中国_中债国债到期收益率_1年!D11+中国_中债国债到期收益率_1年!D10 -> -0.0125 | E12: =-中国_中债国债到期收益率_1年!E11+中国_中债国债到期收益率_1年!E10 -> -0.0024 | F12: =-中国_中债国债到期收益率_1年!F11+中国_中债国债到期收益率_1年!F10 -> -0.0077 | G12: =-中国_中债国债到期收益率_1年!G11+中国_中债国债到期收益率_1年!G10 -> -0.008
A13: 44729 | B13: =-中国_中债国债到期收益率_1年!B12+中国_中债国债到期收益率_1年!B11 -> 0.0008 | C13: =-中国_中债国债到期收益率_1年!C12+中国_中债国债到期收益率_1年!C11 -> 0.0176 | D13: =-中国_中债国债到期收益率_1年!D12+中国_中债国债到期收益率_1年!D11 -> 0.0099 | E13: =-中国_中债国债到期收益率_1年!E12+中国_中债国债到期收益率_1年!E11 -> 0.0099 | F13: =-中国_中债国债到期收益率_1年!F12+中国_中债国债到期收益率_1年!F11 -> 0.0088 | G13: =-中国_中债国债到期收益率_1年!G12+中国_中债国债到期收益率_1年!G11 -> 0.0057
A14: 44732 | B14: =-中国_中债国债到期收益率_1年!B13+中国_中债国债到期收益率_1年!B12 -> 0.025 | C14: =-中国_中债国债到期收益率_1年!C13+中国_中债国债到期收益率_1年!C12 -> -0.0008 | D14: =-中国_中债国债到期收益率_1年!D13+中国_中债国债到期收益率_1年!D12 -> -0.0024 | E14: =-中国_中债国债到期收益率_1年!E13+中国_中债国债到期收益率_1年!E12 -> 0.0025 | F14: =-中国_中债国债到期收益率_1年!F13+中国_中债国债到期收益率_1年!F12 -> 0.0124 | G14: =-中国_中债国债到期收益率_1年!G13+中国_中债国债到期收益率_1年!G12 -> 0.0104
A15: 44733 | B15: =-中国_中债国债到期收益率_1年!B14+中国_中债国债到期收益率_1年!B13 -> 0.0046 | C15: =-中国_中债国债到期收益率_1年!C14+中国_中债国债到期收益率_1年!C13 -> -0.0219 | D15: =-中国_中债国债到期收益率_1年!D14+中国_中债国债到期收益率_1年!D13 -> -0.0101 | E15: =-中国_中债国债到期收益率_1年!E14+中国_中债国债到期收益率_1年!E13 -> -0.0076 | F15: =-中国_中债国债到期收益率_1年!F14+中国_中债国债到期收益率_1年!F13 -> -0.0253 | G15: =-中国_中债国债到期收益率_1年!G14+中国_中债国债到期收益率_1年!G13 -> -0.0235
... A653: 45660 | B653: =-中国_中债国债到期收益率_1年!B652+中国_中债国债到期收益率_1年!B651 -> 0.015 | C653: =-中国_中债国债到期收益率_1年!C652+中国_中债国债到期收益率_1年!C651 -> 0.0176 | D653: =-中国_中债国债到期收益率_1年!D652+中国_中债国债到期收益率_1年!D651 -> 0.0675 | E653: =-中国_中债国债到期收益率_1年!E652+中国_中债国债到期收益率_1年!E651 -> 0.0724 | F653: =-中国_中债国债到期收益率_1年!F652+中国_中债国债到期收益率_1年!F651 -> -0.0048 | G653: =-中国_中债国债到期收益率_1年!G652+中国_中债国债到期收益率_1年!G651 -> 0.0266
A654: 45663
A655: 45664
A656: 45665
A657: 45666
A658: 45667
A659: 45670
A660: 45671
A661: 45672
A662: 45673
A663: 45674

Sheet PnL
A1: 日期 | B1: Bond1Y | C1: Bond5Y | D1: Bond10Y | E1: Bond30Y | F1: Sum | G1: Bond1Y | H1: Bond5Y | I1: Bond10Y | J1: Bond30Y | K1: Sum | L1: DVBond1Y | M1: Bond5Y | N1: Bond10Y | O1: Bond30Y | P1: Sum | Q1: Capcumsum | R1: CarryBond1Y | S1: Bond5Y | T1: Bond10Y | U1: Bond30Y | V1: Sum | W1: Carrycumsum | X1: Cost | Y1: CostCum | Z1: IRS1Y | AA1: IRS5Y | AB1: IRS1YPnL | AC1: IRS5YPnL | AD1: cumsum | AE1: total | AF1: NetValue | AG1: daliyRet | AH1: MDD | AI1: 500000
A2: 44713 | B2: 10 | F2: =SUM(B2:E2) -> 10 | G2: =B2 -> 10 | H2: =5*C2 -> 0 | I2: =9*D2 -> 0 | J2: =16*E2 -> 0 | K2: =SUM(G2:J2) -> 10
A3: 44714 | B3: 10 | F3: =SUM(B3:E3) -> 10 | G3: =B3 -> 10 | H3: =5*C3 -> 0 | I3: =9*D3 -> 0 | J3: =16*E3 -> 0 | K3: =SUM(G3:J3) -> 10 | L3: =G3*Return!B3*100 -> 0 | M3: =H3*Return!C3*100 -> 0 | N3: =I3*Return!D3*100 -> 0 | O3: =J3*Return!E3*100 -> 0 | P3: =SUM(L3:O3) -> 0 | Q3: =SUM($P$3:P3) -> 0 | R3: =B3*中国_中债国债到期收益率_1年!B2/365*100 -> #VALUE! | S3: =C3*中国_中债国债到期收益率_1年!C2/365*100 -> 0 | T3: =D3*中国_中债国债到期收益率_1年!D2/365*100 -> 0 | U3: =E3*中国_中债国债到期收益率_1年!E2/365*100 -> 0 | V3: =SUM(R3:U3) -> #VALUE! | W3: =SUM($V$3:V3) -> #VALUE! | X3: =MAX(F3-50,0)*中国_中债国债到期收益率_1年!H3*100/365 -> 0 | Y3: =SUM($X$3:X3) -> 0 | AA3: -20 | AB3: =Z3*Return!F3*100 -> 0 | AD3: =SUM($AB$3:AB3)+SUM($AC$3:AC3) -> 0 | AE3: =Q3+W3+AD3-Y3 -> #VALUE! | AF3: =AE3/$AI$1+1 -> #VALUE!
A4: 44718 | B4: 10 | F4: =SUM(B4:E4) -> 10 | G4: =B4 -> 10 | H4: =5*C4 -> 0 | J4: =16*E4 -> 0 | K4: =SUM(G4:J4) -> 10 | L4: =G4*Return!B4*100 -> #VALUE! | M4: =H4*Return!C4*100 -> 0 | N4: =I4*Return!D4*100 -> 0 | O4: =J4*Return!E4*100 -> 0 | P4: =SUM(L4:O4) -> #VALUE! | Q4: =SUM($P$3:P4) -> #VALUE! | R4: =B4*中国_中债国债到期收益率_1年!B3/365*100 -> 5.36 | S4: =C4*中国_中债国债到期收益率_1年!C3/365*100 -> 0 | T4: =D4*中国_中债国债到期收益率_1年!D3/365*100 -> 0 | U4: =E4*中国_中债国债到期收益率_1年!E3/365*100 -> 0 | V4: =SUM(R4:U4) -> 5.36 | W4: =SUM($V$3:V4) -> #VALUE! | X4: =MAX(F4-50,0)*中国_中债国债到期收益率_1年!H4*100/365 -> 0 | Y4: =SUM($X$3:X4) -> 0 | AA4: -20 | AB4: =Z4*Return!F4*100 -> 0 | AC4: =AA4*Return!G4*100 -> 28.6 | AD4: =SUM($AB$3:AB4)+SUM($AC$3:AC4) -> 28.6 | AE4: =Q4+W4+AD4-Y4 -> #VALUE! | AF4: =AE4/$AI$1+1 -> #VALUE! | AG4: =(AF4/AF3-1)-中国_中债国债到期收益率_1年!H4%/252 -> #VALUE! | AH4: =MIN((AF4-MAX($AF$3:AF4))/MAX($AF$3:AF4),0) -> #VALUE!
A5: 44719 | B5: 10 | F5: =SUM(B5:E5) -> 10 | G5: =B5 -> 10 | H5: =5*C5 -> 0 | J5: =16*E5 -> 0 | K5: =SUM(G5:J5) -> 10 | L5: =G5*Return!B5*100 -> -63.5 | M5: =H5*Return!C5*100 -> 0 | N5: =I5*Return!D5*100 -> 0 | O5: =J5*Return!E5*100 -> 0 | P5: =SUM(L5:O5) -> -63.5 | Q5: =SUM($P$3:P5) -> #VALUE! | R5: =B5*中国_中债国债到期收益率_1年!B4/365*100 -> 5.5339726 | S5: =C5*中国_中债国债到期收益率_1年!C4/365*100 -> 0 | T5: =D5*中国_中债国债到期收益率_1年!D4/365*100 -> 0 | U5: =E5*中国_中债国债到期收益率_1年!E4/365*100 -> 0 | V5: =SUM(R5:U5) -> 5.5339726 | W5: =SUM($V$3:V5) -> #VALUE! | X5: =MAX(F5-50,0)*中国_中债国债到期收益率_1年!H5*100/365 -> 0 | Y5: =SUM($X$3:X5) -> 0 | AA5: -50 | AB5: =Z5*Return!F5*100 -> 0 | AC5: =AA5*Return!G5*100 -> 93 | AD5: =SUM($AB$3:AB5)+SUM($AC$3:AC5) -> 121.6 | AE5: =Q5+W5+AD5-Y5 -> #VALUE! | AF5: =AE5/$AI$1+1 -> #VALUE! | AG5: =(AF5/AF4-1)-中国_中债国债到期收益率_1年!H5%/252 -> #VALUE! | AH5: =MIN((AF5-MAX($AF$3:AF5))/MAX($AF$3:AF5),0) -> #VALUE!
A6: 44720 | B6: 10 | F6: =SUM(B6:E6) -> 10 | G6: =B6 -> 10 | H6: =5*C6 -> 0 | J6: =16*E6 -> 0 | K6: =SUM(G6:J6) -> 10 | L6: =G6*Return!B6*100 -> 1.9 | M6: =H6*Return!C6*100 -> 0 | N6: =I6*Return!D6*100 -> 0 | O6: =J6*Return!E6*100 -> 0 | P6: =SUM(L6:O6) -> 1.9 | Q6: =SUM($P$3:P6) -> #VALUE! | R6: =B6*中国_中债国债到期收益率_1年!B5/365*100 -> 5.5287671 | S6: =C6*中国_中债国债到期收益率_1年!C5/365*100 -> 0 | T6: =D6*中国_中债国债到期收益率_1年!D5/365*100 -> 0 | U6: =E6*中国_中债国债到期收益率_1年!E5/365*100 -> 0 | V6: =SUM(R6:U6) -> 5.5287671 | W6: =SUM($V$3:V6) -> #VALUE! | X6: =MAX(F6-50,0)*中国_中债国债到期收益率_1年!H6*100/365 -> 0 | Y6: =SUM($X$3:X6) -> 0 | AA6: -50 | AB6: =Z6*Return!F6*100 -> 0 | AC6: =AA6*Return!G6*100 -> 22 | AD6: =SUM($AB$3:AB6)+SUM($AC$3:AC6) -> 143.6 | AE6: =Q6+W6+AD6-Y6 -> #VALUE! | AF6: =AE6/$AI$1+1 -> #VALUE! | AG6: =(AF6/AF5-1)-中国_中债国债到期收益率_1年!H6%/252 -> #VALUE! | AH6: =MIN((AF6-MAX($AF$3:AF6))/MAX($AF$3:AF6),0) -> #VALUE!
A7: 44721 | B7: 10 | F7: =SUM(B7:E7) -> 10 | G7: =B7 -> 10 | H7: =5*C7 -> 0 | J7: =16*E7 -> 0 | K7: =SUM(G7:J7) -> 10 | L7: =G7*Return!B7*100 -> -10.2 | M7: =H7*Return!C7*100 -> 0 | N7: =I7*Return!D7*100 -> 0 | O7: =J7*Return!E7*100 -> 0 | P7: =SUM(L7:O7) -> -10.2 | Q7: =SUM($P$3:P7) -> #VALUE! | R7: =B7*中国_中债国债到期收益率_1年!B6/365*100 -> 5.5567123 | S7: =C7*中国_中债国债到期收益率_1年!C6/365*100 -> 0 | T7: =D7*中国_中债国债到期收益率_1年!D6/365*100 -> 0 | U7: =E7*中国_中债国债到期收益率_1年!E6/365*100 -> 0 | V7: =SUM(R7:U7) -> 5.5567123 | W7: =SUM($V$3:V7) -> #VALUE! | X7: =MAX(F7-50,0)*中国_中债国债到期收益率_1年!H7*100/365 -> 0 | Y7: =SUM($X$3:X7) -> 0 | AA7: -50 | AB7: =Z7*Return!F7*100 -> 0 | AC7: =AA7*Return!G7*100 -> -63.5 | AD7: =SUM($AB$3:AB7)+SUM($AC$3:AC7) -> 80.1 | AE7: =Q7+W7+AD7-Y7 -> #VALUE! | AF7: =AE7/$AI$1+1 -> #VALUE! | AG7: =(AF7/AF6-1)-中国_中债国债到期收益率_1年!H7%/252 -> #VALUE! | AH7: =MIN((AF7-MAX($AF$3:AF7))/MAX($AF$3:AF7),0) -> #VALUE!
A8: 44722 | B8: 10 | F8: =SUM(B8:E8) -> 10 | G8: =B8 -> 10 | H8: =5*C8 -> 0 | J8: =16*E8 -> 0 | K8: =SUM(G8:J8) -> 10 | L8: =G8*Return!B8*100 -> 13.1 | M8: =H8*Return!C8*100 -> 0 | N8: =I8*Return!D8*100 -> 0 | O8: =J8*Return!E8*100 -> 0 | P8: =SUM(L8:O8) -> 13.1 | Q8: =SUM($P$3:P8) -> #VALUE! | R8: =B8*中国_中债国债到期收益率_1年!B7/365*100 -> 5.5208219 | S8: =C8*中国_中债国债到期收益率_1年!C7/365*100 -> 0 | T8: =D8*中国_中债国债到期收益率_1年!D7/365*100 -> 0 | U8: =E8*中国_中债国债到期收益率_1年!E7/365*100 -> 0 | V8: =SUM(R8:U8) -> 5.5208219 | W8: =SUM($V$3:V8) -> #VALUE! | X8: =MAX(F8-50,0)*中国_中债国债到期收益率_1年!H8*100/365 -> 0 | Y8: =SUM($X$3:X8) -> 0 | AA8: -50 | AB8: =Z8*Return!F8*100 -> 0 | AC8: =AA8*Return!G8*100 -> -39.5 | AD8: =SUM($AB$3:AB8)+SUM($AC$3:AC8) -> 40.6 | AE8: =Q8+W8+AD8-Y8 -> #VALUE! | AF8: =AE8/$AI$1+1 -> #VALUE! | AG8: =(AF8/AF7-1)-中国_中债国债到期收益率_1年!H8%/252 -> #VALUE! | AH8: =MIN((AF8-MAX($AF$3:AF8))/MAX($AF$3:AF8),0) -> #VALUE!
A9: 44725 | B9: 10 | F9: =SUM(B9:E9) -> 10 | G9: =B9 -> 10 | H9: =5*C9 -> 0 | J9: =16*E9 -> 0 | K9: =SUM(G9:J9) -> 10 | L9: =G9*Return!B9*100 -> 10 | M9: =H9*Return!C9*100 -> 0 | N9: =I9*Return!D9*100 -> 0 | O9: =J9*Return!E9*100 -> 0 | P9: =SUM(L9:O9) -> 10 | Q9: =SUM($P$3:P9) -> #VALUE! | R9: =B9*中国_中债国债到期收益率_1年!B8/365*100 -> 5.4934247 | S9: =C9*中国_中债国债到期收益率_1年!C8/365*100 -> 0 | T9: =D9*中国_中债国债到期收益率_1年!D8/365*100 -> 0 | U9: =E9*中国_中债国债到期收益率_1年!E8/365*100 -> 0 | V9: =SUM(R9:U9) -> 5.4934247 | W9: =SUM($V$3:V9) -> #VALUE! | X9: =MAX(F9-50,0)*中国_中债国债到期收益率_1年!H9*100/365 -> 0 | Y9: =SUM($X$3:X9) -> 0 | AA9: -50 | AB9: =Z9*Return!F9*100 -> 0 | AC9: =AA9*Return!G9*100 -> -26.5 | AD9: =SUM($AB$3:AB9)+SUM($AC$3:AC9) -> 14.1 | AE9: =Q9+W9+AD9-Y9 -> #VALUE! | AF9: =AE9/$AI$1+1 -> #VALUE! | AG9: =(AF9/AF8-1)-中国_中债国债到期收益率_1年!H9%/252 -> #VALUE! | AH9: =MIN((AF9-MAX($AF$3:AF9))/MAX($AF$3:AF9),0) -> #VALUE!
A10: 44726 | B10: 10 | F10: =SUM(B10:E10) -> 10 | G10: =B10 -> 10 | H10: =5*C10 -> 0 | J10: =16*E10 -> 0 | K10: =SUM(G10:J10) -> 10 | L10: =G10*Return!B10*100 -> 2.5 | M10: =H10*Return!C10*100 -> 0 | N10: =I10*Return!D10*100 -> 0 | O10: =J10*Return!E10*100 -> 0 | P10: =SUM(L10:O10) -> 2.5 | Q10: =SUM($P$3:P10) -> #VALUE! | R10: =B10*中国_中债国债到期收益率_1年!B9/365*100 -> 5.4865753 | S10: =C10*中国_中债国债到期收益率_1年!C9/365*100 -> 0 | T10: =D10*中国_中债国债到期收益率_1年!D9/365*100 -> 0 | U10: =E10*中国_中债国债到期收益率_1年!E9/365*100 -> 0 | V10: =SUM(R10:U10) -> 5.4865753 | W10: =SUM($V$3:V10) -> #VALUE! | X10: =MAX(F10-50,0)*中国_中债国债到期收益率_1年!H10*100/365 -> 0 | Y10: =SUM($X$3:X10) -> 0 | AA10: -50 | AB10: =Z10*Return!F10*100 -> 0 | AC10: =AA10*Return!G10*100 -> 69.5 | AD10: =SUM($AB$3:AB10)+SUM($AC$3:AC10) -> 83.6 | AE10: =Q10+W10+AD10-Y10 -> #VALUE! | AF10: =AE10/$AI$1+1 -> #VALUE! | AG10: =(AF10/AF9-1)-中国_中债国债到期收益率_1年!H10%/252 -> #VALUE! | AH10: =MIN((AF10-MAX($AF$3:AF10))/MAX($AF$3:AF10),0) -> #VALUE!
A11: 44727 | B11: 10 | F11: =SUM(B11:E11) -> 10 | G11: =B11 -> 10 | H11: =5*C11 -> 0 | J11: =16*E11 -> 0 | K11: =SUM(G11:J11) -> 10 | L11: =G11*Return!B11*100 -> -15 | M11: =H11*Return!C11*100 -> 0 | N11: =I11*Return!D11*100 -> 0 | O11: =J11*Return!E11*100 -> 0 | P11: =SUM(L11:O11) -> -15 | Q11: =SUM($P$3:P11) -> #VALUE! | R11: =B11*中国_中债国债到期收益率_1年!B10/365*100 -> 5.5276712 | S11: =C11*中国_中债国债到期收益率_1年!C10/365*100 -> 0 | T11: =D11*中国_中债国债到期收益率_1年!D10/365*100 -> 0 | U11: =E11*中国_中债国债到期收益率_1年!E10/365*100 -> 0 | V11: =SUM(R11:U11) -> 5.5276712 | W11: =SUM($V$3:V11) -> #VALUE! | X11: =MAX(F11-50,0)*中国_中债国债到期收益率_1年!H11*100/365 -> 0 | Y11: =SUM($X$3:X11) -> 0 | AA11: -50 | AB11: =Z11*Return!F11*100 -> 0 | AC11: =AA11*Return!G11*100 -> 84 | AD11: =SUM($AB$3:AB11)+SUM($AC$3:AC11) -> 167.6 | AE11: =Q11+W11+AD11-Y11 -> #VALUE! | AF11: =AE11/$AI$1+1 -> #VALUE! | AG11: =(AF11/AF10-1)-中国_中债国债到期收益率_1年!H11%/252 -> #VALUE! | AH11: =MIN((AF11-MAX($AF$3:AF11))/MAX($AF$3:AF11),0) -> #VALUE!
A12: 44728 | B12: 10 | F12: =SUM(B12:E12) -> 10 | G12: =B12 -> 10 | H12: =5*C12 -> 0 | J12: =16*E12 -> 0 | K12: =SUM(G12:J12) -> 10 | L12: =G12*Return!B12*100 -> -18.4 | M12: =H12*Return!C12*100 -> 0 | N12: =I12*Return!D12*100 -> 0 | O12: =J12*Return!E12*100 -> 0 | P12: =SUM(L12:O12) -> -18.4 | Q12: =SUM($P$3:P12) -> #VALUE! | R12: =B12*中国_中债国债到期收益率_1年!B11/365*100 -> 5.5780822 | S12: =C12*中国_中债国债到期收益率_1年!C11/365*100 -> 0 | T12: =D12*中国_中债国债到期收益率_1年!D11/365*100 -> 0 | U12: =E12*中国_中债国债到期收益率_1年!E11/365*100 -> 0 | V12: =SUM(R12:U12) -> 5.5780822 | W12: =SUM($V$3:V12) -> #VALUE! | X12: =MAX(F12-50,0)*中国_中债国债到期收益率_1年!H12*100/365 -> 0 | Y12: =SUM($X$3:X12) -> 0 | AA12: -50 | AB12: =Z12*Return!F12*100 -> 0 | AC12: =AA12*Return!G12*100 -> 40 | AD12: =SUM($AB$3:AB12)+SUM($AC$3:AC12) -> 207.6 | AE12: =Q12+W12+AD12-Y12 -> #VALUE! | AF12: =AE12/$AI$1+1 -> #VALUE! | AG12: =(AF12/AF11-1)-中国_中债国债到期收益率_1年!H12%/252 -> #VALUE! | AH12: =MIN((AF12-MAX($AF$3:AF12))/MAX($AF$3:AF12),0) -> #VALUE!
A13: 44729 | B13: 10 | C13: 10 | F13: =SUM(B13:E13) -> 20 | G13: =B13 -> 10 | H13: =5*C13 -> 50 | J13: =16*E13 -> 0 | K13: =SUM(G13:J13) -> 60 | L13: =G13*Return!B13*100 -> 0.8 | M13: =H13*Return!C13*100 -> 88 | N13: =I13*Return!D13*100 -> 0 | O13: =J13*Return!E13*100 -> 0 | P13: =SUM(L13:O13) -> 88.8 | Q13: =SUM($P$3:P13) -> #VALUE! | R13: =B13*中国_中债国债到期收益率_1年!B12/365*100 -> 5.5758904 | S13: =C13*中国_中债国债到期收益率_1年!C12/365*100 -> 7.1057534 | T13: =D13*中国_中债国债到期收益率_1年!D12/365*100 -> 0 | U13: =E13*中国_中债国债到期收益率_1年!E12/365*100 -> 0 | V13: =SUM(R13:U13) -> 12.681644 | W13: =SUM($V$3:V13) -> #VALUE! | X13: =MAX(F13-50,0)*中国_中债国债到期收益率_1年!H13*100/365 -> 0 | Y13: =SUM($X$3:X13) -> 0 | AA13: -50 | AB13: =Z13*Return!F13*100 -> 0 | AC13: =AA13*Return!G13*100 -> -28.5 | AD13: =SUM($AB$3:AB13)+SUM($AC$3:AC13) -> 179.1 | AE13: =Q13+W13+AD13-Y13 -> #VALUE! | AF13: =AE13/$AI$1+1 -> #VALUE! | AG13: =(AF13/AF12-1)-中国_中债国债到期收益率_1年!H13%/252 -> #VALUE! | AH13: =MIN((AF13-MAX($AF$3:AF13))/MAX($AF$3:AF13),0) -> #VALUE!
A14: 44732 | B14: 10 | C14: 10 | F14: =SUM(B14:E14) -> 20 | G14: =B14 -> 10 | H14: =5*C14 -> 50 | J14: =16*E14 -> 0 | K14: =SUM(G14:J14) -> 60 | L14: =G14*Return!B14*100 -> 25 | M14: =H14*Return!C14*100 -> -4 | N14: =I14*Return!D14*100 -> 0 | O14: =J14*Return!E14*100 -> 0 | P14: =SUM(L14:O14) -> 21 | Q14: =SUM($P$3:P14) -> #VALUE! | R14: =B14*中国_中债国债到期收益率_1年!B13/365*100 -> 5.5073973 | S14: =C14*中国_中债国债到期收益率_1年!C13/365*100 -> 7.1079452 | T14: =D14*中国_中债国债到期收益率_1年!D13/365*100 -> 0 | U14: =E14*中国_中债国债到期收益率_1年!E13/365*100 -> 0 | V14: =SUM(R14:U14) -> 12.615342 | W14: =SUM($V$3:V14) -> #VALUE! | X14: =MAX(F14-50,0)*中国_中债国债到期收益率_1年!H14*100/365 -> 0 | Y14: =SUM($X$3:X14) -> 0 | AA14: -50 | AB14: =Z14*Return!F14*100 -> 0 | AC14: =AA14*Return!G14*100 -> -52 | AD14: =SUM($AB$3:AB14)+SUM($AC$3:AC14) -> 127.1 | AE14: =Q14+W14+AD14-Y14 -> #VALUE! | AF14: =AE14/$AI$1+1 -> #VALUE! | AG14: =(AF14/AF13-1)-中国_中债国债到期收益率_1年!H14%/252 -> #VALUE! | AH14: =MIN((AF14-MAX($AF$3:AF14))/MAX($AF$3:AF14),0) -> #VALUE!
A15: 44733 | B15: 10 | C15: 10 | F15: =SUM(B15:E15) -> 20 | G15: =B15 -> 10 | H15: =5*C15 -> 50 | J15: =16*E15 -> 0 | K15: =SUM(G15:J15) -> 60 | L15: =G15*Return!B15*100 -> 4.6 | M15: =H15*Return!C15*100 -> -109.5 | N15: =I15*Return!D15*100 -> 0 | O15: =J15*Return!E15*100 -> 0 | P15: =SUM(L15:O15) -> -104.9 | Q15: =SUM($P$3:P15) -> #VALUE! | R15: =B15*中国_中债国债到期收益率_1年!B14/365*100 -> 5.4947945 | S15: =C15*中国_中债国债到期收益率_1年!C14/365*100 -> 7.1679452 | T15: =D15*中国_中债国债到期收益率_1年!D14/365*100 -> 0 | U15: =E15*中国_中债国债到期收益率_1年!E14/365*100 -> 0 | V15: =SUM(R15:U15) -> 12.66274 | W15: =SUM($V$3:V15) -> #VALUE! | X15: =MAX(F15-50,0)*中国_中债国债到期收益率_1年!H15*100/365 -> 0 | Y15: =SUM($X$3:X15) -> 0 | AA15: -50 | AB15: =Z15*Return!F15*100 -> 0 | AC15: =AA15*Return!G15*100 -> 117.5 | AD15: =SUM($AB$3:AB15)+SUM($AC$3:AC15) -> 244.6 | AE15: =Q15+W15+AD15-Y15 -> #VALUE! | AF15: =AE15/$AI$1+1 -> #VALUE! | AG15: =(AF15/AF14-1)-中国_中债国债到期收益率_1年!H15%/252 -> #VALUE! | AH15: =MIN((AF15-MAX($AF$3:AF15))/MAX($AF$3:AF15),0) -> #VALUE!
A16: 44734 | B16: 20 | C16: 10 | F16: =SUM(B16:E16) -> 30 | G16: =B16 -> 20 | H16: =5*C16 -> 50 | J16: =16*E16 -> 0 | K16: =SUM(G16:J16) -> 70 | L16: =G16*Return!B16*100 -> 7.6 | M16: =H16*Return!C16*100 -> 22.5 | N16: =I16*Return!D16*100 -> 0 | O16: =J16*Return!E16*100 -> 0 | P16: =SUM(L16:O16) -> 30.1 | Q16: =SUM($P$3:P16) -> #VALUE! | R16: =B16*中国_中债国债到期收益率_1年!B15/365*100 -> 10.968767 | S16: =C16*中国_中债国债到期收益率_1年!C15/365*100 -> 7.1556164 | T16: =D16*中国_中债国债到期收益率_1年!D15/365*100 -> 0 | U16: =E16*中国_中债国债到期收益率_1年!E15/365*100 -> 0 | V16: =SUM(R16:U16) -> 18.124384 | W16: =SUM($V$3:V16) -> #VALUE! | X16: =MAX(F16-50,0)*中国_中债国债到期收益率_1年!H16*100/365 -> 0 | Y16: =SUM($X$3:X16) -> 0 | AA16: -50 | AB16: =Z16*Return!F16*100 -> 0 | AC16: =AA16*Return!G16*100 -> 39 | AD16: =SUM($AB$3:AB16)+SUM($AC$3:AC16) -> 283.6 | AE16: =Q16+W16+AD16-Y16 -> #VALUE! | AF16: =AE16/$AI$1+1 -> #VALUE! | AG16: =(AF16/AF15-1)-中国_中债国债到期收益率_1年!H16%/252 -> #VALUE! | AH16: =MIN((AF16-MAX($AF$3:AF16))/MAX($AF$3:AF16),0) -> #VALUE!
A17: 44735 | B17: 20 | C17: 10 | F17: =SUM(B17:E17) -> 30 | G17: =B17 -> 20 | H17: =5*C17 -> 50 | J17: =16*E17 -> 0 | K17: =SUM(G17:J17) -> 70 | L17: =G17*Return!B17*100 -> 29.8 | M17: =H17*Return!C17*100 -> 36.5 | N17: =I17*Return!D17*100 -> 0 | O17: =J17*Return!E17*100 -> 0 | P17: =SUM(L17:O17) -> 66.3 | Q17: =SUM($P$3:P17) -> #VALUE! | R17: =B17*中国_中债国债到期收益率_1年!B16/365*100 -> 10.887123 | S17: =C17*中国_中债国债到期收益率_1年!C16/365*100 -> 7.1356164 | T17: =D17*中国_中债国债到期收益率_1年!D16/365*100 -> 0 | U17: =E17*中国_中债国债到期收益率_1年!E16/365*100 -> 0 | V17: =SUM(R17:U17) -> 18.02274 | W17: =SUM($V$3:V17) -> #VALUE! | X17: =MAX(F17-50,0)*中国_中债国债到期收益率_1年!H17*100/365 -> 0 | Y17: =SUM($X$3:X17) -> 0 | AA17: -50 | AB17: =Z17*Return!F17*100 -> 0 | AC17: =AA17*Return!G17*100 -> -53.5 | AD17: =SUM($AB$3:AB17)+SUM($AC$3:AC17) -> 230.1 | AE17: =Q17+W17+AD17-Y17 -> #VALUE! | AF17: =AE17/$AI$1+1 -> #VALUE! | AG17: =(AF17/AF16-1)-中国_中债国债到期收益率_1年!H17%/252 -> #VALUE! | AH17: =MIN((AF17-MAX($AF$3:AF17))/MAX($AF$3:AF17),0) -> #VALUE!
A18: 44736 | B18: 20 | C18: 10 | F18: =SUM(B18:E18) -> 30 | G18: =B18 -> 20 | H18: =5*C18 -> 50 | J18: =16*E18 -> 0 | K18: =SUM(G18:J18) -> 70 | L18: =G18*Return!B18*100 -> 52.2 | M18: =H18*Return!C18*100 -> -16 | N18: =I18*Return!D18*100 -> 0 | O18: =J18*Return!E18*100 -> 0 | P18: =SUM(L18:O18) -> 36.2 | Q18: =SUM($P$3:P18) -> #VALUE! | R18: =B18*中国_中债国债到期收益率_1年!B17/365*100 -> 10.74411 | S18: =C18*中国_中债国债到期收益率_1年!C17/365*100 -> 7.1443836 | T18: =D18*中国_中债国债到期收益率_1年!D17/365*100 -> 0 | U18: =E18*中国_中债国债到期收益率_1年!E17/365*100 -> 0 | V18: =SUM(R18:U18) -> 17.888493 | W18: =SUM($V$3:V18) -> #VALUE! | X18: =MAX(F18-50,0)*中国_中债国债到期收益率_1年!H18*100/365 -> 0 | Y18: =SUM($X$3:X18) -> 0 | AA18: -50 | AB18: =Z18*Return!F18*100 -> 0 | AC18: =AA18*Return!G18*100 -> -28 | AD18: =SUM($AB$3:AB18)+SUM($AC$3:AC18) -> 202.1 | AE18: =Q18+W18+AD18-Y18 -> #VALUE! | AF18: =AE18/$AI$1+1 -> #VALUE! | AG18: =(AF18/AF17-1)-中国_中债国债到期收益率_1年!H18%/252 -> #VALUE! | AH18: =MIN((AF18-MAX($AF$3:AF18))/MAX($AF$3:AF18),0) -> #VALUE!
A19: 44739 | B19: 20 | C19: 10 | F19: =SUM(B19:E19) -> 30 | G19: =B19 -> 20 | H19: =5*C19 -> 50 | I19: =9*D19 -> 0 | J19: =16*E19 -> 0 | K19: =SUM(G19:J19) -> 70 | L19: =G19*Return!B19*100 -> -9 | M19: =H19*Return!C19*100 -> -131.5 | N19: =I19*Return!D19*100 -> 0 | O19: =J19*Return!E19*100 -> 0 | P19: =SUM(L19:O19) -> -140.5 | Q19: =SUM($P$3:P19) -> #VALUE! | R19: =B19*中国_中债国债到期收益率_1年!B18/365*100 -> 10.768767 | S19: =C19*中国_中债国债到期收益率_1年!C18/365*100 -> 7.2164384 | T19: =D19*中国_中债国债到期收益率_1年!D18/365*100 -> 0 | U19: =E19*中国_中债国债到期收益率_1年!E18/365*100 -> 0 | V19: =SUM(R19:U19) -> 17.985205 | W19: =SUM($V$3:V19) -> #VALUE! | X19: =MAX(F19-50,0)*中国_中债国债到期收益率_1年!H19*100/365 -> 0 | Y19: =SUM($X$3:X19) -> 0 | AA19: -50 | AB19: =Z19*Return!F19*100 -> 0 | AC19: =AA19*Return!G19*100 -> 106 | AD19: =SUM($AB$3:AB19)+SUM($AC$3:AC19) -> 308.1 | AE19: =Q19+W19+AD19-Y19 -> #VALUE! | AF19: =AE19/$AI$1+1 -> #VALUE! | AG19: =(AF19/AF18-1)-中国_中债国债到期收益率_1年!H19%/252 -> #VALUE! | AH19: =MIN((AF19-MAX($AF$3:AF19))/MAX($AF$3:AF19),0) -> #VALUE!
A20: 44740 | B20: 20 | C20: 10 | F20: =SUM(B20:E20) -> 30 | G20: =B20 -> 20 | H20: =5*C20 -> 50 | I20: =9*D20 -> 0 | J20: =16*E20 -> 0 | K20: =SUM(G20:J20) -> 70 | L20: =G20*Return!B20*100 -> -63.6 | M20: =H20*Return!C20*100 -> -182 | N20: =I20*Return!D20*100 -> 0 | O20: =J20*Return!E20*100 -> 0 | P20: =SUM(L20:O20) -> -245.6 | Q20: =SUM($P$3:P20) -> #VALUE! | R20: =B20*中国_中债国债到期收益率_1年!B19/365*100 -> 10.943014 | S20: =C20*中国_中债国债到期收益率_1年!C19/365*100 -> 7.3161644 | T20: =D20*中国_中债国债到期收益率_1年!D19/365*100 -> 0 | U20: =E20*中国_中债国债到期收益率_1年!E19/365*100 -> 0 | V20: =SUM(R20:U20) -> 18.259178 | W20: =SUM($V$3:V20) -> #VALUE! | X20: =MAX(F20-50,0)*中国_中债国债到期收益率_1年!H20*100/365 -> 0 | Y20: =SUM($X$3:X20) -> 0 | AA20: -50 | AB20: =Z20*Return!F20*100 -> 0 | AC20: =AA20*Return!G20*100 -> 220 | AD20: =SUM($AB$3:AB20)+SUM($AC$3:AC20) -> 528.1 | AE20: =Q20+W20+AD20-Y20 -> #VALUE! | AF20: =AE20/$AI$1+1 -> #VALUE! | AG20: =(AF20/AF19-1)-中国_中债国债到期收益率_1年!H20%/252 -> #VALUE! | AH20: =MIN((AF20-MAX($AF$3:AF20))/MAX($AF$3:AF20),0) -> #VALUE!
A21: 44741 | B21: 20 | C21: 10 | F21: =SUM(B21:E21) -> 30 | G21: =B21 -> 20 | H21: =5*C21 -> 50 | I21: =9*D21 -> 0 | J21: =16*E21 -> 0 | K21: =SUM(G21:J21) -> 70 | L21: =G21*Return!B21*100 -> -1 | M21: =H21*Return!C21*100 -> -60.5 | N21: =I21*Return!D21*100 -> 0 | O21: =J21*Return!E21*100 -> 0 | P21: =SUM(L21:O21) -> -61.5 | Q21: =SUM($P$3:P21) -> #VALUE! | R21: =B21*中国_中债国债到期收益率_1年!B20/365*100 -> 10.945753 | S21: =C21*中国_中债国债到期收益率_1年!C20/365*100 -> 7.3493151 | T21: =D21*中国_中债国债到期收益率_1年!D20/365*100 -> 0 | U21: =E21*中国_中债国债到期收益率_1年!E20/365*100 -> 0 | V21: =SUM(R21:U21) -> 18.295068 | W21: =SUM($V$3:V21) -> #VALUE! | X21: =MAX(F21-50,0)*中国_中债国债到期收益率_1年!H21*100/365 -> 0 | Y21: =SUM($X$3:X21) -> 0 | AA21: -50 | AB21: =Z21*Return!F21*100 -> 0 | AC21: =AA21*Return!G21*100 -> 56 | AD21: =SUM($AB$3:AB21)+SUM($AC$3:AC21) -> 584.1 | AE21: =Q21+W21+AD21-Y21 -> #VALUE! | AF21: =AE21/$AI$1+1 -> #VALUE! | AG21: =(AF21/AF20-1)-中国_中债国债到期收益率_1年!H21%/252 -> #VALUE! | AH21: =MIN((AF21-MAX($AF$3:AF21))/MAX($AF$3:AF21),0) -> #VALUE!
A22: 44742 | B22: 20 | C22: 10 | F22: =SUM(B22:E22) -> 30 | G22: =B22 -> 20 | H22: =5*C22 -> 50 | I22: =9*D22 -> 0 | J22: =16*E22 -> 0 | K22: =SUM(G22:J22) -> 70 | L22: =G22*Return!B22*100 -> 42.6 | M22: =H22*Return!C22*100 -> 46.5 | N22: =I22*Return!D22*100 -> 0 | O22: =J22*Return!E22*100 -> 0 | P22: =SUM(L22:O22) -> 89.1 | Q22: =SUM($P$3:P22) -> #VALUE! | R22: =B22*中国_中债国债到期收益率_1年!B21/365*100 -> 10.829041 | S22: =C22*中国_中债国债到期收益率_1年!C21/365*100 -> 7.3238356 | T22: =D22*中国_中债国债到期收益率_1年!D21/365*100 -> 0 | U22: =E22*中国_中债国债到期收益率_1年!E21/365*100 -> 0 | V22: =SUM(R22:U22) -> 18.152877 | W22: =SUM($V$3:V22) -> #VALUE! | X22: =MAX(F22-50,0)*中国_中债国债到期收益率_1年!H22*100/365 -> 0 | Y22: =SUM($X$3:X22) -> 0 | AA22: -50 | AB22: =Z22*Return!F22*100 -> 0 | AC22: =AA22*Return!G22*100 -> -15 | AD22: =SUM($AB$3:AB22)+SUM($AC$3:AC22) -> 569.1 | AE22: =Q22+W22+AD22-Y22 -> #VALUE! | AF22: =AE22/$AI$1+1 -> #VALUE! | AG22: =(AF22/AF21-1)-中国_中债国债到期收益率_1年!H22%/252 -> #VALUE! | AH22: =MIN((AF22-MAX($AF$3:AF22))/MAX($AF$3:AF22),0) -> #VALUE!
A23: 44743 | B23: 20 | C23: 10 | F23: =SUM(B23:E23) -> 30 | G23: =B23 -> 20 | H23: =5*C23 -> 50 | I23: =9*D23 -> 0 | J23: =16*E23 -> 0 | K23: =SUM(G23:J23) -> 70 | L23: =G23*Return!B23*100 -> 51.8 | M23: =H23*Return!C23*100 -> 101.5 | N23: =I23*Return!D23*100 -> 0 | O23: =J23*Return!E23*100 -> 0 | P23: =SUM(L23:O23) -> 153.3 | Q23: =SUM($P$3:P23) -> #VALUE! | R23: =B23*中国_中债国债到期收益率_1年!B22/365*100 -> 10.687123 | S23: =C23*中国_中债国债到期收益率_1年!C22/365*100 -> 7.2682192 | T23: =D23*中国_中债国债到期收益率_1年!D22/365*100 -> 0 | U23: =E23*中国_中债国债到期收益率_1年!E22/365*100 -> 0 | V23: =SUM(R23:U23) -> 17.955342 | W23: =SUM($V$3:V23) -> #VALUE! | X23: =MAX(F23-50,0)*中国_中债国债到期收益率_1年!H23*100/365 -> 0 | Y23: =SUM($X$3:X23) -> 0 | AA23: -50 | AB23: =Z23*Return!F23*100 -> 0 | AC23: =AA23*Return!G23*100 -> -77.5 | AD23: =SUM($AB$3:AB23)+SUM($AC$3:AC23) -> 491.6 | AE23: =Q23+W23+AD23-Y23 -> #VALUE! | AF23: =AE23/$AI$1+1 -> #VALUE! | AG23: =(AF23/AF22-1)-中国_中债国债到期收益率_1年!H23%/252 -> #VALUE! | AH23: =MIN((AF23-MAX($AF$3:AF23))/MAX($AF$3:AF23),0) -> #VALUE!
A24: 44746 | B24: 20 | C24: 10 | F24: =SUM(B24:E24) -> 30 | G24: =B24 -> 20 | H24: =5*C24 -> 50 | I24: =9*D24 -> 0 | J24: =16*E24 -> 0 | K24: =SUM(G24:J24) -> 70 | L24: =G24*Return!B24*100 -> 36 | M24: =H24*Return!C24*100 -> 22 | N24: =I24*Return!D24*100 -> 0 | O24: =J24*Return!E24*100 -> 0 | P24: =SUM(L24:O24) -> 58 | Q24: =SUM($P$3:P24) -> #VALUE! | R24: =B24*中国_中债国债到期收益率_1年!B23/365*100 -> 10.588493 | S24: =C24*中国_中债国债到期收益率_1年!C23/365*100 -> 7.2561644 | T24: =D24*中国_中债国债到期收益率_1年!D23/365*100 -> 0 | U24: =E24*中国_中债国债到期收益率_1年!E23/365*100 -> 0 | V24: =SUM(R24:U24) -> 17.844658 | W24: =SUM($V$3:V24) -> #VALUE! | X24: =MAX(F24-50,0)*中国_中债国债到期收益率_1年!H24*100/365 -> 0 | Y24: =SUM($X$3:X24) -> 0 | AA24: -50 | AB24: =Z24*Return!F24*100 -> 0 | AC24: =AA24*Return!G24*100 -> -60.5 | AD24: =SUM($AB$3:AB24)+SUM($AC$3:AC24) -> 431.1 | AE24: =Q24+W24+AD24-Y24 -> #VALUE! | AF24: =AE24/$AI$1+1 -> #VALUE! | AG24: =(AF24/AF23-1)-中国_中债国债到期收益率_1年!H24%/252 -> #VALUE! | AH24: =MIN((AF24-MAX($AF$3:AF24))/MAX($AF$3:AF24),0) -> #VALUE!
A25: 44747 | B25: 20 | C25: 10 | F25: =SUM(B25:E25) -> 30 | G25: =B25 -> 20 | H25: =5*C25 -> 50 | I25: =9*D25 -> 0 | J25: =16*E25 -> 0 | K25: =SUM(G25:J25) -> 70 | L25: =G25*Return!B25*100 -> -101.4 | M25: =H25*Return!C25*100 -> -240 | N25: =I25*Return!D25*100 -> 0 | O25: =J25*Return!E25*100 -> 0 | P25: =SUM(L25:O25) -> -341.4 | Q25: =SUM($P$3:P25) -> #VALUE! | R25: =B25*中国_中债国债到期收益率_1年!B24/365*100 -> 10.866301 | S25: =C25*中国_中债国债到期收益率_1年!C24/365*100 -> 7.3876712 | T25: =D25*中国_中债国债到期收益率_1年!D24/365*100 -> 0 | U25: =E25*中国_中债国债到期收益率_1年!E24/365*100 -> 0 | V25: =SUM(R25:U25) -> 18.253973 | W25: =SUM($V$3:V25) -> #VALUE! | X25: =MAX(F25-50,0)*中国_中债国债到期收益率_1年!H25*100/365 -> 0 | Y25: =SUM($X$3:X25) -> 0 | AA25: -50 | AB25: =Z25*Return!F25*100 -> 0 | AC25: =AA25*Return!G25*100 -> 227 | AD25: =SUM($AB$3:AB25)+SUM($AC$3:AC25) -> 658.1 | AE25: =Q25+W25+AD25-Y25 -> #VALUE! | AF25: =AE25/$AI$1+1 -> #VALUE! | AG25: =(AF25/AF24-1)-中国_中债国债到期收益率_1年!H25%/252 -> #VALUE! | AH25: =MIN((AF25-MAX($AF$3:AF25))/MAX($AF$3:AF25),0) -> #VALUE!
A26: 44748 | B26: 10 | C26: 10 | F26: =SUM(B26:E26) -> 20 | G26: =B26 -> 10 | H26: =5*C26 -> 50 | I26: =9*D26 -> 0 | J26: =16*E26 -> 0 | K26: =SUM(G26:J26) -> 60 | L26: =G26*Return!B26*100 -> -26.9 | M26: =H26*Return!C26*100 -> 17.5 | N26: =I26*Return!D26*100 -> 0 | O26: =J26*Return!E26*100 -> 0 | P26: =SUM(L26:O26) -> -9.4 | Q26: =SUM($P$3:P26) -> #VALUE! | R26: =B26*中国_中债国债到期收益率_1年!B25/365*100 -> 5.5068493 | S26: =C26*中国_中债国债到期收益率_1年!C25/365*100 -> 7.3780822 | T26: =D26*中国_中债国债到期收益率_1年!D25/365*100 -> 0 | U26: =E26*中国_中债国债到期收益率_1年!E25/365*100 -> 0 | V26: =SUM(R26:U26) -> 12.884932 | W26: =SUM($V$3:V26) -> #VALUE! | X26: =MAX(F26-50,0)*中国_中债国债到期收益率_1年!H26*100/365 -> 0 | Y26: =SUM($X$3:X26) -> 0 | AA26: -50 | AB26: =Z26*Return!F26*100 -> 0 | AC26: =AA26*Return!G26*100 -> 101 | AD26: =SUM($AB$3:AB26)+SUM($AC$3:AC26) -> 759.1 | AE26: =Q26+W26+AD26-Y26 -> #VALUE! | AF26: =AE26/$AI$1+1 -> #VALUE! | AG26: =(AF26/AF25-1)-中国_中债国债到期收益率_1年!H26%/252 -> #VALUE! | AH26: =MIN((AF26-MAX($AF$3:AF26))/MAX($AF$3:AF26),0) -> #VALUE!
A27: 44749 | B27: 10 | C27: 10 | D27: 10 | F27: =SUM(B27:E27) -> 30 | G27: =B27 -> 10 | H27: =5*C27 -> 50 | I27: =9*D27 -> 90 | J27: =16*E27 -> 0 | K27: =SUM(G27:J27) -> 150 | L27: =G27*Return!B27*100 -> 18.9 | M27: =H27*Return!C27*100 -> 14 | N27: =I27*Return!D27*100 -> -20.7 | O27: =J27*Return!E27*100 -> 0 | P27: =SUM(L27:O27) -> 12.2 | Q27: =SUM($P$3:P27) -> #VALUE! | R27: =B27*中国_中债国债到期收益率_1年!B26/365*100 -> 5.4550685 | S27: =C27*中国_中债国债到期收益率_1年!C26/365*100 -> 7.370411 | T27: =D27*中国_中债国债到期收益率_1年!D26/365*100 -> 7.7687671 | U27: =E27*中国_中债国债到期收益率_1年!E26/365*100 -> 0 | V27: =SUM(R27:U27) -> 20.594247 | W27: =SUM($V$3:V27) -> #VALUE! | X27: =MAX(F27-50,0)*中国_中债国债到期收益率_1年!H27*100/365 -> 0 | Y27: =SUM($X$3:X27) -> 0 | AA27: -50 | AB27: =Z27*Return!F27*100 -> 0 | AC27: =AA27*Return!G27*100 -> -87 | AD27: =SUM($AB$3:AB27)+SUM($AC$3:AC27) -> 672.1 | AE27: =Q27+W27+AD27-Y27 -> #VALUE! | AF27: =AE27/$AI$1+1 -> #VALUE! | AG27: =(AF27/AF26-1)-中国_中债国债到期收益率_1年!H27%/252 -> #VALUE! | AH27: =MIN((AF27-MAX($AF$3:AF27))/MAX($AF$3:AF27),0) -> #VALUE!
A28: 44750 | B28: 10 | C28: 10 | D28: 10 | F28: =SUM(B28:E28) -> 30 | G28: =B28 -> 10 | H28: =5*C28 -> 50 | I28: =9*D28 -> 90 | J28: =16*E28 -> 0 | K28: =SUM(G28:J28) -> 150 | L28: =G28*Return!B28*100 -> 8.7 | M28: =H28*Return!C28*100 -> 22.5 | N28: =I28*Return!D28*100 -> 0 | O28: =J28*Return!E28*100 -> 0 | P28: =SUM(L28:O28) -> 31.2 | Q28: =SUM($P$3:P28) -> #VALUE! | R28: =B28*中国_中债国债到期收益率_1年!B27/365*100 -> 5.4312329 | S28: =C28*中国_中债国债到期收益率_1年!C27/365*100 -> 7.3580822 | T28: =D28*中国_中债国债到期收益率_1年!D27/365*100 -> 7.7687671 | U28: =E28*中国_中债国债到期收益率_1年!E27/365*100 -> 0 | V28: =SUM(R28:U28) -> 20.558082 | W28: =SUM($V$3:V28) -> #VALUE! | X28: =MAX(F28-50,0)*中国_中债国债到期收益率_1年!H28*100/365 -> 0 | Y28: =SUM($X$3:X28) -> 0 | AB28: =Z28*Return!F28*100 -> 0 | AC28: =AA28*Return!G28*100 -> 0 | AD28: =SUM($AB$3:AB28)+SUM($AC$3:AC28) -> 672.1 | AE28: =Q28+W28+AD28-Y28 -> #VALUE! | AF28: =AE28/$AI$1+1 -> #VALUE! | AG28: =(AF28/AF27-1)-中国_中债国债到期收益率_1年!H28%/252 -> #VALUE! | AH28: =MIN((AF28-MAX($AF$3:AF28))/MAX($AF$3:AF28),0) -> #VALUE!
A29: 44753 | B29: 10 | C29: 10 | D29: 10 | F29: =SUM(B29:E29) -> 30 | G29: =B29 -> 10 | H29: =5*C29 -> 50 | I29: =9*D29 -> 90 | J29: =16*E29 -> 0 | K29: =SUM(G29:J29) -> 150 | L29: =G29*Return!B29*100 -> 24 | M29: =H29*Return!C29*100 -> 36 | N29: =I29*Return!D29*100 -> -25.2 | O29: =J29*Return!E29*100 -> 0 | P29: =SUM(L29:O29) -> 34.8 | Q29: =SUM($P$3:P29) -> #VALUE! | R29: =B29*中国_中债国债到期收益率_1年!B28/365*100 -> 5.3654795 | S29: =C29*中国_中债国债到期收益率_1年!C28/365*100 -> 7.3383562 | T29: =D29*中国_中债国债到期收益率_1年!D28/365*100 -> 7.7764384 | U29: =E29*中国_中债国债到期收益率_1年!E28/365*100 -> 0 | V29: =SUM(R29:U29) -> 20.480274 | W29: =SUM($V$3:V29) -> #VALUE! | X29: =MAX(F29-50,0)*中国_中债国债到期收益率_1年!H29*100/365 -> 0 | Y29: =SUM($X$3:X29) -> 0 | AB29: =Z29*Return!F29*100 -> 0 | AC29: =AA29*Return!G29*100 -> 0 | AD29: =SUM($AB$3:AB29)+SUM($AC$3:AC29) -> 672.1 | AE29: =Q29+W29+AD29-Y29 -> #VALUE! | AF29: =AE29/$AI$1+1 -> #VALUE! | AG29: =(AF29/AF28-1)-中国_中债国债到期收益率_1年!H29%/252 -> #VALUE! | AH29: =MIN((AF29-MAX($AF$3:AF29))/MAX($AF$3:AF29),0) -> #VALUE!
A30: 44754 | B30: 10 | C30: 10 | D30: 10 | F30: =SUM(B30:E30) -> 30 | G30: =B30 -> 10 | H30: =5*C30 -> 50 | I30: =9*D30 -> 90 | J30: =16*E30 -> 0 | K30: =SUM(G30:J30) -> 150 | L30: =G30*Return!B30*100 -> 16.7 | M30: =H30*Return!C30*100 -> 125 | N30: =I30*Return!D30*100 -> 106.2 | O30: =J30*Return!E30*100 -> 0 | P30: =SUM(L30:O30) -> 247.9 | Q30: =SUM($P$3:P30) -> #VALUE! | R30: =B30*中国_中债国债到期收益率_1年!B29/365*100 -> 5.319726 | S30: =C30*中国_中债国债到期收益率_1年!C29/365*100 -> 7.269863 | T30: =D30*中国_中债国债到期收益率_1年!D29/365*100 -> 7.7441096 | U30: =E30*中国_中债国债到期收益率_1年!E29/365*100 -> 0 | V30: =SUM(R30:U30) -> 20.333699 | W30: =SUM($V$3:V30) -> #VALUE! | X30: =MAX(F30-50,0)*中国_中债国债到期收益率_1年!H30*100/365 -> 0 | Y30: =SUM($X$3:X30) -> 0 | AB30: =Z30*Return!F30*100 -> 0 | AC30: =AA30*Return!G30*100 -> 0 | AD30: =SUM($AB$3:AB30)+SUM($AC$3:AC30) -> 672.1 | AE30: =Q30+W30+AD30-Y30 -> #VALUE! | AF30: =AE30/$AI$1+1 -> #VALUE! | AG30: =(AF30/AF29-1)-中国_中债国债到期收益率_1年!H30%/252 -> #VALUE! | AH30: =MIN((AF30-MAX($AF$3:AF30))/MAX($AF$3:AF30),0) -> #VALUE!
A31: 44755 | B31: 10 | C31: 10 | D31: 10 | F31: =SUM(B31:E31) -> 30 | G31: =B31 -> 10 | H31: =5*C31 -> 50 | I31: =9*D31 -> 90 | J31: =16*E31 -> 0 | K31: =SUM(G31:J31) -> 150 | L31: =G31*Return!B31*100 -> 7.2 | M31: =H31*Return!C31*100 -> 163 | N31: =I31*Return!D31*100 -> 134.1 | O31: =J31*Return!E31*100 -> 0 | P31: =SUM(L31:O31) -> 304.3 | Q31: =SUM($P$3:P31) -> #VALUE! | R31: =B31*中国_中债国债到期收益率_1年!B30/365*100 -> 5.3 | S31: =C31*中国_中债国债到期收益率_1年!C30/365*100 -> 7.1805479 | T31: =D31*中国_中债国债到期收益率_1年!D30/365*100 -> 7.7032877 | U31: =E31*中国_中债国债到期收益率_1年!E30/365*100 -> 0 | V31: =SUM(R31:U31) -> 20.183836 | W31: =SUM($V$3:V31) -> #VALUE! | X31: =MAX(F31-50,0)*中国_中债国债到期收益率_1年!H31*100/365 -> 0 | Y31: =SUM($X$3:X31) -> 0 | AB31: =Z31*Return!F31*100 -> 0 | AC31: =AA31*Return!G31*100 -> 0 | AD31: =SUM($AB$3:AB31)+SUM($AC$3:AC31) -> 672.1 | AE31: =Q31+W31+AD31-Y31 -> #VALUE! | AF31: =AE31/$AI$1+1 -> #VALUE! | AG31: =(AF31/AF30-1)-中国_中债国债到期收益率_1年!H31%/252 -> #VALUE! | AH31: =MIN((AF31-MAX($AF$3:AF31))/MAX($AF$3:AF31),0) -> #VALUE!
A32: 44756 | B32: 10 | C32: 10 | D32: 10 | F32: =SUM(B32:E32) -> 30 | G32: =B32 -> 10 | H32: =5*C32 -> 50 | I32: =9*D32 -> 90 | J32: =16*E32 -> 0 | K32: =SUM(G32:J32) -> 150 | L32: =G32*Return!B32*100 -> -3.1 | M32: =H32*Return!C32*100 -> 37.5 | N32: =I32*Return!D32*100 -> 45 | O32: =J32*Return!E32*100 -> 0 | P32: =SUM(L32:O32) -> 79.4 | Q32: =SUM($P$3:P32) -> #VALUE! | R32: =B32*中国_中债国债到期收益率_1年!B31/365*100 -> 5.3084932 | S32: =C32*中国_中债国债到期收益率_1年!C31/365*100 -> 7.16 | T32: =D32*中国_中债国债到期收益率_1年!D31/365*100 -> 7.689589 | U32: =E32*中国_中债国债到期收益率_1年!E31/365*100 -> 0 | V32: =SUM(R32:U32) -> 20.158082 | W32: =SUM($V$3:V32) -> #VALUE! | X32: =MAX(F32-50,0)*中国_中债国债到期收益率_1年!H32*100/365 -> 0 | Y32: =SUM($X$3:X32) -> 0 | AB32: =Z32*Return!F32*100 -> 0 | AC32: =AA32*Return!G32*100 -> 0 | AD32: =SUM($AB$3:AB32)+SUM($AC$3:AC32) -> 672.1 | AE32: =Q32+W32+AD32-Y32 -> #VALUE! | AF32: =AE32/$AI$1+1 -> #VALUE! | AG32: =(AF32/AF31-1)-中国_中债国债到期收益率_1年!H32%/252 -> #VALUE! | AH32: =MIN((AF32-MAX($AF$3:AF32))/MAX($AF$3:AF32),0) -> #VALUE!
A33: 44757 | B33: 10 | C33: 10 | D33: 10 | F33: =SUM(B33:E33) -> 30 | G33: =B33 -> 10 | H33: =5*C33 -> 50 | I33: =9*D33 -> 90 | J33: =16*E33 -> 0 | K33: =SUM(G33:J33) -> 150 | L33: =G33*Return!B33*100 -> 22.9 | M33: =H33*Return!C33*100 -> 132 | N33: =I33*Return!D33*100 -> 144 | O33: =J33*Return!E33*100 -> 0 | P33: =SUM(L33:O33) -> 298.9 | Q33: =SUM($P$3:P33) -> #VALUE! | R33: =B33*中国_中债国债到期收益率_1年!B32/365*100 -> 5.2457534 | S33: =C33*中国_中债国债到期收益率_1年!C32/365*100 -> 7.0876712 | T33: =D33*中国_中债国债到期收益率_1年!D32/365*100 -> 7.6457534 | U33: =E33*中国_中债国债到期收益率_1年!E32/365*100 -> 0 | V33: =SUM(R33:U33) -> 19.979178 | W33: =SUM($V$3:V33) -> #VALUE! | X33: =MAX(F33-50,0)*中国_中债国债到期收益率_1年!H33*100/365 -> 0 | Y33: =SUM($X$3:X33) -> 0 | AB33: =Z33*Return!F33*100 -> 0 | AC33: =AA33*Return!G33*100 -> 0 | AD33: =SUM($AB$3:AB33)+SUM($AC$3:AC33) -> 672.1 | AE33: =Q33+W33+AD33-Y33 -> #VALUE! | AF33: =AE33/$AI$1+1 -> #VALUE! | AG33: =(AF33/AF32-1)-中国_中债国债到期收益率_1年!H33%/252 -> #VALUE! | AH33: =MIN((AF33-MAX($AF$3:AF33))/MAX($AF$3:AF33),0) -> #VALUE!
A34: 44760 | B34: 10 | C34: 10 | D34: 10 | F34: =SUM(B34:E34) -> 30 | G34: =B34 -> 10 | H34: =5*C34 -> 50 | I34: =9*D34 -> 90 | J34: =16*E34 -> 0 | K34: =SUM(G34:J34) -> 150 | L34: =G34*Return!B34*100 -> 31 | M34: =H34*Return!C34*100 -> 11 | N34: =I34*Return!D34*100 -> 45 | O34: =J34*Return!E34*100 -> 0 | P34: =SUM(L34:O34) -> 87 | Q34: =SUM($P$3:P34) -> #VALUE! | R34: =B34*中国_中债国债到期收益率_1年!B33/365*100 -> 5.1608219 | S34: =C34*中国_中债国债到期收益率_1年!C33/365*100 -> 7.0816438 | T34: =D34*中国_中债国债到期收益率_1年!D33/365*100 -> 7.6320548 | U34: =E34*中国_中债国债到期收益率_1年!E33/365*100 -> 0 | V34: =SUM(R34:U34) -> 19.874521 | W34: =SUM($V$3:V34) -> #VALUE! | X34: =MAX(F34-50,0)*中国_中债国债到期收益率_1年!H34*100/365 -> 0 | Y34: =SUM($X$3:X34) -> 0 | AB34: =Z34*Return!F34*100 -> 0 | AC34: =AA34*Return!G34*100 -> 0 | AD34: =SUM($AB$3:AB34)+SUM($AC$3:AC34) -> 672.1 | AE34: =Q34+W34+AD34-Y34 -> #VALUE! | AF34: =AE34/$AI$1+1 -> #VALUE! | AG34: =(AF34/AF33-1)-中国_中债国债到期收益率_1年!H34%/252 -> #VALUE! | AH34: =MIN((AF34-MAX($AF$3:AF34))/MAX($AF$3:AF34),0) -> #VALUE!
A35: 44761 | B35: 10 | C35: 10 | D35: 10 | F35: =SUM(B35:E35) -> 30 | G35: =B35 -> 10 | H35: =5*C35 -> 50 | I35: =9*D35 -> 90 | J35: =16*E35 -> 0 | K35: =SUM(G35:J35) -> 150 | L35: =G35*Return!B35*100 -> 34.9 | M35: =H35*Return!C35*100 -> 29.5 | N35: =I35*Return!D35*100 -> 18 | O35: =J35*Return!E35*100 -> 0 | P35: =SUM(L35:O35) -> 82.4 | Q35: =SUM($P$3:P35) -> #VALUE! | R35: =B35*中国_中债国债到期收益率_1年!B34/365*100 -> 5.0652055 | S35: =C35*中国_中债国债到期收益率_1年!C34/365*100 -> 7.0654795 | T35: =D35*中国_中债国债到期收益率_1年!D34/365*100 -> 7.6265753 | U35: =E35*中国_中债国债到期收益率_1年!E34/365*100 -> 0 | V35: =SUM(R35:U35) -> 19.75726 | W35: =SUM($V$3:V35) -> #VALUE! | X35: =MAX(F35-50,0)*中国_中债国债到期收益率_1年!H35*100/365 -> 0 | Y35: =SUM($X$3:X35) -> 0 | AB35: =Z35*Return!F35*100 -> 0 | AC35: =AA35*Return!G35*100 -> 0 | AD35: =SUM($AB$3:AB35)+SUM($AC$3:AC35) -> 672.1 | AE35: =Q35+W35+AD35-Y35 -> #VALUE! | AF35: =AE35/$AI$1+1 -> #VALUE! | AG35: =(AF35/AF34-1)-中国_中债国债到期收益率_1年!H35%/252 -> #VALUE! | AH35: =MIN((AF35-MAX($AF$3:AF35))/MAX($AF$3:AF35),0) -> #VALUE!
A36: 44762 | B36: 10 | C36: 10 | D36: 10 | F36: =SUM(B36:E36) -> 30 | G36: =B36 -> 10 | H36: =5*C36 -> 50 | I36: =9*D36 -> 90 | J36: =16*E36 -> 0 | K36: =SUM(G36:J36) -> 150 | L36: =G36*Return!B36*100 -> -0.3 | M36: =H36*Return!C36*100 -> -39.5 | N36: =I36*Return!D36*100 -> -19.8 | O36: =J36*Return!E36*100 -> 0 | P36: =SUM(L36:O36) -> -59.6 | Q36: =SUM($P$3:P36) -> #VALUE! | R36: =B36*中国_中债国债到期收益率_1年!B35/365*100 -> 5.0660274 | S36: =C36*中国_中债国债到期收益率_1年!C35/365*100 -> 7.0871233 | T36: =D36*中国_中债国债到期收益率_1年!D35/365*100 -> 7.6326027 | U36: =E36*中国_中债国债到期收益率_1年!E35/365*100 -> 0 | V36: =SUM(R36:U36) -> 19.785753 | W36: =SUM($V$3:V36) -> #VALUE! | X36: =MAX(F36-50,0)*中国_中债国债到期收益率_1年!H36*100/365 -> 0 | Y36: =SUM($X$3:X36) -> 0 | AB36: =Z36*Return!F36*100 -> 0 | AC36: =AA36*Return!G36*100 -> 0 | AD36: =SUM($AB$3:AB36)+SUM($AC$3:AC36) -> 672.1 | AE36: =Q36+W36+AD36-Y36 -> #VALUE! | AF36: =AE36/$AI$1+1 -> #VALUE! | AG36: =(AF36/AF35-1)-中国_中债国债到期收益率_1年!H36%/252 -> #VALUE! | AH36: =MIN((AF36-MAX($AF$3:AF36))/MAX($AF$3:AF36),0) -> #VALUE!
A37: 44763 | B37: 10 | C37: 10 | D37: 10 | F37: =SUM(B37:E37) -> 30 | G37: =B37 -> 10 | H37: =5*C37 -> 50 | I37: =9*D37 -> 90 | J37: =16*E37 -> 0 | K37: =SUM(G37:J37) -> 150 | L37: =G37*Return!B37*100 -> -22.1 | M37: =H37*Return!C37*100 -> 117 | N37: =I37*Return!D37*100 -> 134.1 | O37: =J37*Return!E37*100 -> 0 | P37: =SUM(L37:O37) -> 229 | Q37: =SUM($P$3:P37) -> #VALUE! | R37: =B37*中国_中债国债到期收益率_1年!B36/365*100 -> 5.1265753 | S37: =C37*中国_中债国债到期收益率_1年!C36/365*100 -> 7.0230137 | T37: =D37*中国_中债国债到期收益率_1年!D36/365*100 -> 7.5917808 | U37: =E37*中国_中债国债到期收益率_1年!E36/365*100 -> 0 | V37: =SUM(R37:U37) -> 19.74137 | W37: =SUM($V$3:V37) -> #VALUE! | X37: =MAX(F37-50,0)*中国_中债国债到期收益率_1年!H37*100/365 -> 0 | Y37: =SUM($X$3:X37) -> 0 | AB37: =Z37*Return!F37*100 -> 0 | AC37: =AA37*Return!G37*100 -> 0 | AD37: =SUM($AB$3:AB37)+SUM($AC$3:AC37) -> 672.1 | AE37: =Q37+W37+AD37-Y37 -> #VALUE! | AF37: =AE37/$AI$1+1 -> #VALUE! | AG37: =(AF37/AF36-1)-中国_中债国债到期收益率_1年!H37%/252 -> #VALUE! | AH37: =MIN((AF37-MAX($AF$3:AF37))/MAX($AF$3:AF37),0) -> #VALUE!
A38: 44764 | B38: 10 | C38: 10 | D38: 10 | F38: =SUM(B38:E38) -> 30 | G38: =B38 -> 10 | H38: =5*C38 -> 50 | I38: =9*D38 -> 90 | J38: =16*E38 -> 0 | K38: =SUM(G38:J38) -> 150 | L38: =G38*Return!B38*100 -> -0.5 | M38: =H38*Return!C38*100 -> 59 | N38: =I38*Return!D38*100 -> 67.5 | O38: =J38*Return!E38*100 -> 0 | P38: =SUM(L38:O38) -> 126 | Q38: =SUM($P$3:P38) -> #VALUE! | R38: =B38*中国_中债国债到期收益率_1年!B37/365*100 -> 5.1279452 | S38: =C38*中国_中债国债到期收益率_1年!C37/365*100 -> 6.9906849 | T38: =D38*中国_中债国债到期收益率_1年!D37/365*100 -> 7.5712329 | U38: =E38*中国_中债国债到期收益率_1年!E37/365*100 -> 0 | V38: =SUM(R38:U38) -> 19.689863 | W38: =SUM($V$3:V38) -> #VALUE! | X38: =MAX(F38-50,0)*中国_中债国债到期收益率_1年!H38*100/365 -> 0 | Y38: =SUM($X$3:X38) -> 0 | AB38: =Z38*Return!F38*100 -> 0 | AC38: =AA38*Return!G38*100 -> 0 | AD38: =SUM($AB$3:AB38)+SUM($AC$3:AC38) -> 672.1 | AE38: =Q38+W38+AD38-Y38 -> #VALUE! | AF38: =AE38/$AI$1+1 -> #VALUE! | AG38: =(AF38/AF37-1)-中国_中债国债到期收益率_1年!H38%/252 -> #VALUE! | AH38: =MIN((AF38-MAX($AF$3:AF38))/MAX($AF$3:AF38),0) -> #VALUE!
